Workbook

Sheet Cleaned DATA
A1: PORT CODE | B1: DATE | C1: IEC | D1: HS CODE | E1: GOODS DESCRIPTION | F1: Master category | G1: Model Name | H1: Model Number | I1: Capacity | J1: Qty | K1: Unit of measure | L1: Price | M1: Unit of measure2 | N1: QUANTITY | O1: UNIT | P1: UNIT PRICE_INR | Q1: TOTAL VALUE_INR | R1: UNIT PRICE_USD | S1: TOTAL VALUE_USD | T1: DUTY PAID_INR | U1: Grand Total_INR | V1: Year | W1: Main Category | X1: Sub Category
A2: INNSA1 | B2: 2025-10-28 | C2: 0301049751 | D2: 73239990 | E2: TH5170 STEEL CUTLERY HOLDER (QTY:600 PCS/USD 2.03 PER PCS) TH5170 STEEL CUTLERY HOLDER (QTY:600 PCS/USD 2.03 PER PCS) | F2: {=_xlfn.LET( _xlpm.txt, E2, _xlpm.clean, TRIM(_xlfn.REGEXREPLACE(_xlpm.txt, "\(QTY[^)]*\)", "")), _xlpm.noBrackets, TRIM(SUBSTITUTE(SUBSTITUTE(_xlpm.clean, "(", ""), ")", "")), _xlpm.words, _xlfn.TEXTSPLIT(_xlpm.noBrackets, " "), _xlpm.firstCode, INDEX(_xlpm.words, 1), _xlpm.category, INDEX(_xlpm.words, 2), _xlpm.category )} -> STEEL | G2: {=_xlfn.LET( _xlpm.txt, TRIM(E2), _xlpm.posQTY, IFERROR(FIND("(QTY", _xlpm.txt, 1), 0), _xlpm.firstSpace, FIND(" ", _xlpm.txt & " "), _xlpm.afterFirst, TRIM(MID(_xlpm.txt, _xlpm.firstSpace+1, 9999)), _xlpm.namePart, IF(_xlpm.posQTY>0, _xlfn.TEXTBEFORE(_xlpm.afterFirst, "(QTY"), IFERROR(_xlfn.TEXTBEFORE(_xlpm.afterFirst, "("), _xlpm.afterFirst)), TRIM(_xlpm.namePart) )} -> STEEL CUTLERY HOLDER | H2: =IFERROR( IF( AND(ISNUMBER(FIND("(",E2)), NOT(ISNUMBER(SEARCH("QTY", _xlfn.TEXTBEFORE(_xlfn.TEXTAFTER(E2,"("), ")")))) ), _xlfn.TEXTBEFORE(_xlfn.TEXTAFTER(E2,"("), ")"), LEFT(E2, FIND(" ", E2 & " ") - 1) ), "") -> TH5170 | I2: {=_xlfn.LET( _xlpm.txt, E2, _xlpm.afterQty, IFERROR(_xlfn.TEXTAFTER(_xlpm.txt, "QTY:"), ""), _xlpm.numberText, TRIM(_xlfn.TEXTBEFORE(_xlpm.afterQty, " ")), _xlpm.cleanNum, SUBSTITUTE(_xlpm.numberText, ",", ""), IF(ISNUMBER(--_xlpm.cleanNum), --_xlpm.cleanNum, "") )} -> 600 | J2: {=_xlfn.LET( _xlpm.txt, E2, _xlpm.afterQ, IFERROR(_xlfn.TEXTAFTER(_xlpm.txt,"QTY:"), IFERROR(_xlfn.TEXTAFTER(_xlpm.txt,"QTY "), IFERROR(_xlfn.TEXTAFTER(_xlpm.txt,"(QTY"), ""))), _xlpm.token, TRIM(IF(_xlpm.afterQ="","", _xlfn.TEXTBEFORE(_xlpm.afterQ, "/"))), _xlpm.numPart, IFERROR(LEFT(_xlpm.token, FIND(" ", _xlpm.token)-1), _xlpm.token), _xlpm.cleanNum, SUBSTITUTE(_xlpm.numPart, ",",""), IF(_xlpm.cleanNum="", "", VALUE(_xlpm.cleanNum)) )} -> 600 | K2: {=_xlfn.LET( _xlpm.txt, E2, _xlpm.afterQ, IFERROR(_xlfn.TEXTAFTER(_xlpm.txt,"QTY:"), IFERROR(_xlfn.TEXTAFTER(_xlpm.txt,"QTY "), IFERROR(_xlfn.TEXTAFTER(_xlpm.txt,"(QTY"), ""))), _xlpm.token, TRIM(IF(_xlpm.afterQ="","", _xlfn.TEXTBEFORE(_xlpm.afterQ, "/"))), _xlpm.unitRaw, UPPER(TRIM(RIGHT(_xlpm.token, LEN(_xlpm.token) - FIND("@", SUBSTITUTE(_xlpm.token," ","@", LEN(_xlpm.token)-LEN(SUBSTITUTE(_xlpm.token," ",""))))))), _xlpm.unitRaw )} -> PCS | L2: {=IFERROR( _xlfn.LET( _xlpm.txt, E2, _xlpm.usdPart, TRIM(_xlfn.TEXTAFTER(_xlpm.txt, "USD")), _xlpm.chars, MID(_xlpm.usdPart, ROW(INDIRECT("1:" & LEN(_xlpm.usdPart))), 1), _xlpm.keep, "0123456789.", _xlpm.filtered, _xlfn.TEXTJOIN("", TRUE, IF(ISNUMBER(FIND(_xlpm.chars, _xlpm.keep)), _xlpm.chars, " ")), _xlpm.firstNum, TRIM(INDEX(_xlfn.TEXTSPLIT(_xlpm.filtered," "),1)), IF(_xlpm.firstNum="", "", VALUE(_xlpm.firstNum)) ), "")} -> 2.03 | M2: =IF(OR(K2="PCS",K2="PC",K2="NOS"),"PCS", IF(OR(K2="SET",K2="SETS"),"SET", IF(K2="PKT","PACK","OTHER"))) -> PCS | N2: 290 | O2: KGS | P2: 401.72531 | Q2: 116500.34 | R2: 4.5290339 | S2: 1313.4198 | T2: 32736.6 | U2: =P2+R2 -> 406.25434 | V2: =YEAR(B2) -> 2025 | W2: =IFERROR(VLOOKUP(VALUE(D2),'HSN Lookup'!$A:$B,2,0),"Unknown") -> Household Steel Items | X2: =IF(ISNUMBER(SEARCH("SCRUBBER",G2)),"Scrubber", IF(ISNUMBER(SEARCH("STRAINER",G2)),"Tea Strainer", IF(ISNUMBER(SEARCH("BASKET",G2)),"Basket", IF(ISNUMBER(SEARCH("HANGER",G2)),"Hanger", IF(ISNUMBER(SEARCH("STAND",G2)),"Cloth Stand", IF(ISNUMBER(SEARCH("SPRINKLER",G2)),"Sprinkler", IF(ISNUMBER(SEARCH("HOLDER",G2)),"Holder", IF(ISNUMBER(SEARCH("LUNCH BOX",G2)),"Lunch Box", "Other")))))))) -> Holder
A3: INNSA1 | B3: 2025-10-28 | C3: 0301049751 | D3: 73231000 | E3: 8001-2 STEEL SCRUBBER 2PCS SET (QTY: 336000 SETS/USD 0.139 PER SETS)8001-2 STEEL SCRUBBER 2PCS SET (QTY: 336000 SETS/USD 0.139 P | F3: {=_xlfn.LET( _xlpm.txt, E3, _xlpm.clean, TRIM(_xlfn.REGEXREPLACE(_xlpm.txt, "\(QTY[^)]*\)", "")), _xlpm.noBrackets, TRIM(SUBSTITUTE(SUBSTITUTE(_xlpm.clean, "(", ""), ")", "")), _xlpm.words, _xlfn.TEXTSPLIT(_xlpm.noBrackets, " "), _xlpm.firstCode, INDEX(_xlpm.words, 1), _xlpm.category, INDEX(_xlpm.words, 2), _xlpm.category )} -> STEEL | G3: {=_xlfn.LET( _xlpm.txt, TRIM(E3), _xlpm.posQTY, IFERROR(FIND("(QTY", _xlpm.txt, 1), 0), _xlpm.firstSpace, FIND(" ", _xlpm.txt & " "), _xlpm.afterFirst, TRIM(MID(_xlpm.txt, _xlpm.firstSpace+1, 9999)), _xlpm.namePart, IF(_xlpm.posQTY>0, _xlfn.TEXTBEFORE(_xlpm.afterFirst, "(QTY"), IFERROR(_xlfn.TEXTBEFORE(_xlpm.afterFirst, "("), _xlpm.afterFirst)), TRIM(_xlpm.namePart) )} -> STEEL SCRUBBER 2PCS SET | H3: =IFERROR( IF( AND(ISNUMBER(FIND("(",E3)), NOT(ISNUMBER(SEARCH("QTY", _xlfn.TEXTBEFORE(_xlfn.TEXTAFTER(E3,"("), ")")))) ), _xlfn.TEXTBEFORE(_xlfn.TEXTAFTER(E3,"("), ")"), LEFT(E3, FIND(" ", E3 & " ") - 1) ), "") -> 8001-2 | I3: {=_xlfn.LET( _xlpm.txt, E3, _xlpm.afterQty, IFERROR(_xlfn.TEXTAFTER(_xlpm.txt, "QTY:"), ""), _xlpm.numberText, TRIM(_xlfn.TEXTBEFORE(_xlpm.afterQty, " ")), _xlpm.cleanNum, SUBSTITUTE(_xlpm.numberText, ",", ""), IF(ISNUMBER(--_xlpm.cleanNum), --_xlpm.cleanNum, "") )} | J3: {=_xlfn.LET( _xlpm.txt, E3, _xlpm.afterQ, IFERROR(_xlfn.TEXTAFTER(_xlpm.txt,"QTY:"), IFERROR(_xlfn.TEXTAFTER(_xlpm.txt,"QTY "), IFERROR(_xlfn.TEXTAFTER(_xlpm.txt,"(QTY"), ""))), _xlpm.token, TRIM(IF(_xlpm.afterQ="","", _xlfn.TEXTBEFORE(_xlpm.afterQ, "/"))), _xlpm.numPart, IFERROR(LEFT(_xlpm.token, FIND(" ", _xlpm.token)-1), _xlpm.token), _xlpm.cleanNum, SUBSTITUTE(_xlpm.numPart, ",",""), IF(_xlpm.cleanNum="", "", VALUE(_xlpm.cleanNum)) )} -> 336000 | K3: {=_xlfn.LET( _xlpm.txt, E3, _xlpm.afterQ, IFERROR(_xlfn.TEXTAFTER(_xlpm.txt,"QTY:"), IFERROR(_xlfn.TEXTAFTER(_xlpm.txt,"QTY "), IFERROR(_xlfn.TEXTAFTER(_xlpm.txt,"(QTY"), ""))), _xlpm.token, TRIM(IF(_xlpm.afterQ="","", _xlfn.TEXTBEFORE(_xlpm.afterQ, "/"))), _xlpm.unitRaw, UPPER(TRIM(RIGHT(_xlpm.token, LEN(_xlpm.token) - FIND("@", SUBSTITUTE(_xlpm.token," ","@", LEN(_xlpm.token)-LEN(SUBSTITUTE(_xlpm.token," ",""))))))), _xlpm.unitRaw )} -> SETS | L3: {=IFERROR( _xlfn.LET( _xlpm.txt, E3, _xlpm.usdPart, TRIM(_xlfn.TEXTAFTER(_xlpm.txt, "USD")), _xlpm.chars, MID(_xlpm.usdPart, ROW(INDIRECT("1:" & LEN(_xlpm.usdPart))), 1), _xlpm.keep, "0123456789.", _xlpm.filtered, _xlfn.TEXTJOIN("", TRUE, IF(ISNUMBER(FIND(_xlpm.chars, _xlpm.keep)), _xlpm.chars, " ")), _xlpm.firstNum, TRIM(INDEX(_xlfn.TEXTSPLIT(_xlpm.filtered," "),1)), IF(_xlpm.firstNum="", "", VALUE(_xlpm.firstNum)) ), "")} -> 0.139 | M3: =IF(OR(K3="PCS",K3="PC",K3="NOS"),"PCS", IF(OR(K3="SET",K3="SETS"),"SET", IF(K3="PKT","PACK","OTHER"))) -> SET | N3: 9800 | O3: KGS | P3: 440.60222 | Q3: 4317901.7 | R3: 4.9673305 | S3: 48679.839 | T3: 1898149.5 | U3: =P3+R3 -> 445.56955 | V3: =YEAR(B3) -> 2025 | W3: =IFERROR(VLOOKUP(VALUE(D3),'HSN Lookup'!$A:$B,2,0),"Unknown") -> Steel Scrubbers | X3: =IF(ISNUMBER(SEARCH("SCRUBBER",G3)),"Scrubber", IF(ISNUMBER(SEARCH("STRAINER",G3)),"Tea Strainer", IF(ISNUMBER(SEARCH("BASKET",G3)),"Basket", IF(ISNUMBER(SEARCH("HANGER",G3)),"Hanger", IF(ISNUMBER(SEARCH("STAND",G3)),"Cloth Stand", IF(ISNUMBER(SEARCH("SPRINKLER",G3)),"Sprinkler", IF(ISNUMBER(SEARCH("HOLDER",G3)),"Holder", IF(ISNUMBER(SEARCH("LUNCH BOX",G3)),"Lunch Box", "Other")))))))) -> Scrubber
A4: INNSA1 | B4: 2025-10-23 | C4: 0301049751 | D4: 73239990 | E4: MILD STEEL MULTI FUNCTION CLOTH STAND (RYX-02-020) (QTY: 1,232 PCS/CNY:101 PER PCS)MILD STEEL MULTI FUNCTION CLOTH STAND (RYX-02-020) (QTY: 1,2 | F4: {=_xlfn.LET( _xlpm.txt, E4, _xlpm.clean, TRIM(_xlfn.REGEXREPLACE(_xlpm.txt, "\(QTY[^)]*\)", "")), _xlpm.noBrackets, TRIM(SUBSTITUTE(SUBSTITUTE(_xlpm.clean, "(", ""), ")", "")), _xlpm.words, _xlfn.TEXTSPLIT(_xlpm.noBrackets, " "), _xlpm.firstCode, INDEX(_xlpm.words, 1), _xlpm.category, INDEX(_xlpm.words, 2), _xlpm.category )} -> STEEL | G4: {=_xlfn.LET( _xlpm.txt, TRIM(E4), _xlpm.posQTY, IFERROR(FIND("(QTY", _xlpm.txt, 1), 0), _xlpm.firstSpace, FIND(" ", _xlpm.txt & " "), _xlpm.afterFirst, TRIM(MID(_xlpm.txt, _xlpm.firstSpace+1, 9999)), _xlpm.namePart, IF(_xlpm.posQTY>0, _xlfn.TEXTBEFORE(_xlpm.afterFirst, "(QTY"), IFERROR(_xlfn.TEXTBEFORE(_xlpm.afterFirst, "("), _xlpm.afterFirst)), TRIM(_xlpm.namePart) )} -> STEEL MULTI FUNCTION CLOTH STAND (RYX-02-020) | H4: =IFERROR( IF( AND(ISNUMBER(FIND("(",E4)), NOT(ISNUMBER(SEARCH("QTY", _xlfn.TEXTBEFORE(_xlfn.TEXTAFTER(E4,"("), ")")))) ), _xlfn.TEXTBEFORE(_xlfn.TEXTAFTER(E4,"("), ")"), LEFT(E4, FIND(" ", E4 & " ") - 1) ), "") -> RYX-02-020 | I4: {=_xlfn.LET( _xlpm.txt, E4, _xlpm.afterQty, IFERROR(_xlfn.TEXTAFTER(_xlpm.txt, "QTY:"), ""), _xlpm.numberText, TRIM(_xlfn.TEXTBEFORE(_xlpm.afterQty, " ")), _xlpm.cleanNum, SUBSTITUTE(_xlpm.numberText, ",", ""), IF(ISNUMBER(--_xlpm.cleanNum), --_xlpm.cleanNum, "") )} | J4: {=_xlfn.LET( _xlpm.txt, E4, _xlpm.afterQ, IFERROR(_xlfn.TEXTAFTER(_xlpm.txt,"QTY:"), IFERROR(_xlfn.TEXTAFTER(_xlpm.txt,"QTY "), IFERROR(_xlfn.TEXTAFTER(_xlpm.txt,"(QTY"), ""))), _xlpm.token, TRIM(IF(_xlpm.afterQ="","", _xlfn.TEXTBEFORE(_xlpm.afterQ, "/"))), _xlpm.numPart, IFERROR(LEFT(_xlpm.token, FIND(" ", _xlpm.token)-1), _xlpm.token), _xlpm.cleanNum, SUBSTITUTE(_xlpm.numPart, ",",""), IF(_xlpm.cleanNum="", "", VALUE(_xlpm.cleanNum)) )} -> 1232 | K4: {=_xlfn.LET( _xlpm.txt, E4, _xlpm.afterQ, IFERROR(_xlfn.TEXTAFTER(_xlpm.txt,"QTY:"), IFERROR(_xlfn.TEXTAFTER(_xlpm.txt,"QTY "), IFERROR(_xlfn.TEXTAFTER(_xlpm.txt,"(QTY"), ""))), _xlpm.token, TRIM(IF(_xlpm.afterQ="","", _xlfn.TEXTBEFORE(_xlpm.afterQ, "/"))), _xlpm.unitRaw, UPPER(TRIM(RIGHT(_xlpm.token, LEN(_xlpm.token) - FIND("@", SUBSTITUTE(_xlpm.token," ","@", LEN(_xlpm.token)-LEN(SUBSTITUTE(_xlpm.token," ",""))))))), _xlpm.unitRaw )} -> PCS | L4: =IFERROR(_xlfn.TEXTAFTER(_xlfn.TEXTBEFORE(E4," PER"),"USD ")," ") | M4: =IF(OR(K4="PCS",K4="PC",K4="NOS"),"PCS", IF(OR(K4="SET",K4="SETS"),"SET", IF(K4="PKT","PACK","OTHER"))) -> PCS | N4: 4004 | O4: KGS | P4: 408.89366 | Q4: 1637210.2 | R4: 4.6098496 | S4: 18457.838 | T4: 460056 | U4: =P4+R4 -> 413.50351 | V4: =YEAR(B4) -> 2025 | W4: =IFERROR(VLOOKUP(VALUE(D4),'HSN Lookup'!$A:$B,2,0),"Unknown") -> Household Steel Items | X4: =IF(ISNUMBER(SEARCH("SCRUBBER",G4)),"Scrubber", IF(ISNUMBER(SEARCH("STRAINER",G4)),"Tea Strainer", IF(ISNUMBER(SEARCH("BASKET",G4)),"Basket", IF(ISNUMBER(SEARCH("HANGER",G4)),"Hanger", IF(ISNUMBER(SEARCH("STAND",G4)),"Cloth Stand", IF(ISNUMBER(SEARCH("SPRINKLER",G4)),"Sprinkler", IF(ISNUMBER(SEARCH("HOLDER",G4)),"Holder", IF(ISNUMBER(SEARCH("LUNCH BOX",G4)),"Lunch Box", "Other")))))))) -> Cloth Stand
A5: INNSA1 | B5: 2025-10-13 | C5: 0301049751 | D5: 73239990 | E5: SB-12 STEEL TEA STRAINER BIG (QTY 6336 PCS/USD 0.973 PER PCS)SB-12 STEEL TEA STRAINER BIG (QTY 6336 PCS/USD 0.973 PER PCS | F5: {=_xlfn.LET( _xlpm.txt, E5, _xlpm.clean, TRIM(_xlfn.REGEXREPLACE(_xlpm.txt, "\(QTY[^)]*\)", "")), _xlpm.noBrackets, TRIM(SUBSTITUTE(SUBSTITUTE(_xlpm.clean, "(", ""), ")", "")), _xlpm.words, _xlfn.TEXTSPLIT(_xlpm.noBrackets, " "), _xlpm.firstCode, INDEX(_xlpm.words, 1), _xlpm.category, INDEX(_xlpm.words, 2), _xlpm.category )} -> STEEL | G5: {=_xlfn.LET( _xlpm.txt, TRIM(E5), _xlpm.posQTY, IFERROR(FIND("(QTY", _xlpm.txt, 1), 0), _xlpm.firstSpace, FIND(" ", _xlpm.txt & " "), _xlpm.afterFirst, TRIM(MID(_xlpm.txt, _xlpm.firstSpace+1, 9999)), _xlpm.namePart, IF(_xlpm.posQTY>0, _xlfn.TEXTBEFORE(_xlpm.afterFirst, "(QTY"), IFERROR(_xlfn.TEXTBEFORE(_xlpm.afterFirst, "("), _xlpm.afterFirst)), TRIM(_xlpm.namePart) )} -> STEEL TEA STRAINER BIG | H5: =IFERROR( IF( AND(ISNUMBER(FIND("(",E5)), NOT(ISNUMBER(SEARCH("QTY", _xlfn.TEXTBEFORE(_xlfn.TEXTAFTER(E5,"("), ")")))) ), _xlfn.TEXTBEFORE(_xlfn.TEXTAFTER(E5,"("), ")"), LEFT(E5, FIND(" ", E5 & " ") - 1) ), "") -> SB-12 | I5: {=_xlfn.LET( _xlpm.txt, E5, _xlpm.afterQty, IFERROR(_xlfn.TEXTAFTER(_xlpm.txt, "QTY:"), ""), _xlpm.numberText, TRIM(_xlfn.TEXTBEFORE(_xlpm.afterQty, " ")), _xlpm.cleanNum, SUBSTITUTE(_xlpm.numberText, ",", ""), IF(ISNUMBER(--_xlpm.cleanNum), --_xlpm.cleanNum, "") )} | J5: {=_xlfn.LET( _xlpm.txt, E5, _xlpm.afterQ, IFERROR(_xlfn.TEXTAFTER(_xlpm.txt,"QTY:"), IFERROR(_xlfn.TEXTAFTER(_xlpm.txt,"QTY "), IFERROR(_xlfn.TEXTAFTER(_xlpm.txt,"(QTY"), ""))), _xlpm.token, TRIM(IF(_xlpm.afterQ="","", _xlfn.TEXTBEFORE(_xlpm.afterQ, "/"))), _xlpm.numPart, IFERROR(LEFT(_xlpm.token, FIND(" ", _xlpm.token)-1), _xlpm.token), _xlpm.cleanNum, SUBSTITUTE(_xlpm.numPart, ",",""), IF(_xlpm.cleanNum="", "", VALUE(_xlpm.cleanNum)) )} -> 6336 | K5: {=_xlfn.LET( _xlpm.txt, E5, _xlpm.afterQ, IFERROR(_xlfn.TEXTAFTER(_xlpm.txt,"QTY:"), IFERROR(_xlfn.TEXTAFTER(_xlpm.txt,"QTY "), IFERROR(_xlfn.TEXTAFTER(_xlpm.txt,"(QTY"), ""))), _xlpm.token, TRIM(IF(_xlpm.afterQ="","", _xlfn.TEXTBEFORE(_xlpm.afterQ, "/"))), _xlpm.unitRaw, UPPER(TRIM(RIGHT(_xlpm.token, LEN(_xlpm.token) - FIND("@", SUBSTITUTE(_xlpm.token," ","@", LEN(_xlpm.token)-LEN(SUBSTITUTE(_xlpm.token," ",""))))))), _xlpm.unitRaw )} -> PCS | L5: =IFERROR(_xlfn.TEXTAFTER(_xlfn.TEXTBEFORE(E5," PER"),"USD ")," ") -> 0.973 | M5: =IF(OR(K5="PCS",K5="PC",K5="NOS"),"PCS", IF(OR(K5="SET",K5="SETS"),"SET", IF(K5="PKT","PACK","OTHER"))) -> PCS | N5: 1548.8 | O5: KGS | P5: 378.45784 | Q5: 586155.51 | R5: 4.219151 | S5: 6534.6211 | T5: 164709.7 | U5: =P5+R5 -> 382.677 | V5: =YEAR(B5) -> 2025 | W5: =IFERROR(VLOOKUP(VALUE(D5),'HSN Lookup'!$A:$B,2,0),"Unknown") -> Household Steel Items | X5: =IF(ISNUMBER(SEARCH("SCRUBBER",G5)),"Scrubber", IF(ISNUMBER(SEARCH("STRAINER",G5)),"Tea Strainer", IF(ISNUMBER(SEARCH("BASKET",G5)),"Basket", IF(ISNUMBER(SEARCH("HANGER",G5)),"Hanger", IF(ISNUMBER(SEARCH("STAND",G5)),"Cloth Stand", IF(ISNUMBER(SEARCH("SPRINKLER",G5)),"Sprinkler", IF(ISNUMBER(SEARCH("HOLDER",G5)),"Holder", IF(ISNUMBER(SEARCH("LUNCH BOX",G5)),"Lunch Box", "Other")))))))) -> Tea Strainer
A6: INNSA1 | B6: 2025-10-13 | C6: 0301049751 | D6: 73239990 | E6: SB-12 STEEL TEA STRAINER BIG (QTY 43038 PCS/USD 0.9718 PER PCS)SB-12 STEEL TEA STRAINER BIG (QTY 43038 PCS/USD 0.9718 PER P | F6: {=_xlfn.LET( _xlpm.txt, E6, _xlpm.clean, TRIM(_xlfn.REGEXREPLACE(_xlpm.txt, "\(QTY[^)]*\)", "")), _xlpm.noBrackets, TRIM(SUBSTITUTE(SUBSTITUTE(_xlpm.clean, "(", ""), ")", "")), _xlpm.words, _xlfn.TEXTSPLIT(_xlpm.noBrackets, " "), _xlpm.firstCode, INDEX(_xlpm.words, 1), _xlpm.category, INDEX(_xlpm.words, 2), _xlpm.category )} -> STEEL | G6: {=_xlfn.LET( _xlpm.txt, TRIM(E6), _xlpm.posQTY, IFERROR(FIND("(QTY", _xlpm.txt, 1), 0), _xlpm.firstSpace, FIND(" ", _xlpm.txt & " "), _xlpm.afterFirst, TRIM(MID(_xlpm.txt, _xlpm.firstSpace+1, 9999)), _xlpm.namePart, IF(_xlpm.posQTY>0, _xlfn.TEXTBEFORE(_xlpm.afterFirst, "(QTY"), IFERROR(_xlfn.TEXTBEFORE(_xlpm.afterFirst, "("), _xlpm.afterFirst)), TRIM(_xlpm.namePart) )} -> STEEL TEA STRAINER BIG | H6: =IFERROR( IF( AND(ISNUMBER(FIND("(",E6)), NOT(ISNUMBER(SEARCH("QTY", _xlfn.TEXTBEFORE(_xlfn.TEXTAFTER(E6,"("), ")")))) ), _xlfn.TEXTBEFORE(_xlfn.TEXTAFTER(E6,"("), ")"), LEFT(E6, FIND(" ", E6 & " ") - 1) ), "") -> SB-12 | I6: {=_xlfn.LET( _xlpm.txt, E6, _xlpm.afterQty, IFERROR(_xlfn.TEXTAFTER(_xlpm.txt, "QTY:"), ""), _xlpm.numberText, TRIM(_xlfn.TEXTBEFORE(_xlpm.afterQty, " ")), _xlpm.cleanNum, SUBSTITUTE(_xlpm.numberText, ",", ""), IF(ISNUMBER(--_xlpm.cleanNum), --_xlpm.cleanNum, "") )} | J6: {=_xlfn.LET( _xlpm.txt, E6, _xlpm.afterQ, IFERROR(_xlfn.TEXTAFTER(_xlpm.txt,"QTY:"), IFERROR(_xlfn.TEXTAFTER(_xlpm.txt,"QTY "), IFERROR(_xlfn.TEXTAFTER(_xlpm.txt,"(QTY"), ""))), _xlpm.token, TRIM(IF(_xlpm.afterQ="","", _xlfn.TEXTBEFORE(_xlpm.afterQ, "/"))), _xlpm.numPart, IFERROR(LEFT(_xlpm.token, FIND(" ", _xlpm.token)-1), _xlpm.token), _xlpm.cleanNum, SUBSTITUTE(_xlpm.numPart, ",",""), IF(_xlpm.cleanNum="", "", VALUE(_xlpm.cleanNum)) )} -> 43038 | K6: {=_xlfn.LET( _xlpm.txt, E6, _xlpm.afterQ, IFERROR(_xlfn.TEXTAFTER(_xlpm.txt,"QTY:"), IFERROR(_xlfn.TEXTAFTER(_xlpm.txt,"QTY "), IFERROR(_xlfn.TEXTAFTER(_xlpm.txt,"(QTY"), ""))), _xlpm.token, TRIM(IF(_xlpm.afterQ="","", _xlfn.TEXTBEFORE(_xlpm.afterQ, "/"))), _xlpm.unitRaw, UPPER(TRIM(RIGHT(_xlpm.token, LEN(_xlpm.token) - FIND("@", SUBSTITUTE(_xlpm.token," ","@", LEN(_xlpm.token)-LEN(SUBSTITUTE(_xlpm.token," ",""))))))), _xlpm.unitRaw )} -> PCS | L6: =IFERROR(_xlfn.TEXTAFTER(_xlfn.TEXTBEFORE(E6," PER"),"USD ")," ") -> 0.9718 | M6: =IF(OR(K6="PCS",K6="PC",K6="NOS"),"PCS", IF(OR(K6="SET",K6="SETS"),"SET", IF(K6="PKT","PACK","OTHER"))) -> PCS | N6: 10042.2 | O6: KGS | P6: 399.73967 | Q6: 4014265.8 | R6: 4.4564066 | S6: 44752.127 | T6: 1128008.7 | U6: =P6+R6 -> 404.19608 | V6: =YEAR(B6) -> 2025 | W6: =IFERROR(VLOOKUP(VALUE(D6),'HSN Lookup'!$A:$B,2,0),"Unknown") -> Household Steel Items | X6: =IF(ISNUMBER(SEARCH("SCRUBBER",G6)),"Scrubber", IF(ISNUMBER(SEARCH("STRAINER",G6)),"Tea Strainer", IF(ISNUMBER(SEARCH("BASKET",G6)),"Basket", IF(ISNUMBER(SEARCH("HANGER",G6)),"Hanger", IF(ISNUMBER(SEARCH("STAND",G6)),"Cloth Stand", IF(ISNUMBER(SEARCH("SPRINKLER",G6)),"Sprinkler", IF(ISNUMBER(SEARCH("HOLDER",G6)),"Holder", IF(ISNUMBER(SEARCH("LUNCH BOX",G6)),"Lunch Box", "Other")))))))) -> Tea Strainer
A7: INNSA1 | B7: 2025-10-08 | C7: 0301049751 | D7: 73239990 | E7: STEEL HANGER WITH HOOK (SL-89) (QTY:70056 PCS/CNY:7.45 PER PCS)STEEL HANGER WITH HOOK (SL-89) (QTY:70056 PCS/:7.45 | F7: {=_xlfn.LET( _xlpm.txt, E7, _xlpm.clean, TRIM(_xlfn.REGEXREPLACE(_xlpm.txt, "\(QTY[^)]*\)", "")), _xlpm.noBrackets, TRIM(SUBSTITUTE(SUBSTITUTE(_xlpm.clean, "(", ""), ")", "")), _xlpm.words, _xlfn.TEXTSPLIT(_xlpm.noBrackets, " "), _xlpm.firstCode, INDEX(_xlpm.words, 1), _xlpm.category, INDEX(_xlpm.words, 2), _xlpm.category )} -> HANGER | G7: {=_xlfn.LET( _xlpm.txt, TRIM(E7), _xlpm.posQTY, IFERROR(FIND("(QTY", _xlpm.txt, 1), 0), _xlpm.firstSpace, FIND(" ", _xlpm.txt & " "), _xlpm.afterFirst, TRIM(MID(_xlpm.txt, _xlpm.firstSpace+1, 9999)), _xlpm.namePart, IF(_xlpm.posQTY>0, _xlfn.TEXTBEFORE(_xlpm.afterFirst, "(QTY"), IFERROR(_xlfn.TEXTBEFORE(_xlpm.afterFirst, "("), _xlpm.afterFirst)), TRIM(_xlpm.namePart) )} -> HANGER WITH HOOK (SL-89) | H7: =IFERROR( IF( AND(ISNUMBER(FIND("(",E7)), NOT(ISNUMBER(SEARCH("QTY", _xlfn.TEXTBEFORE(_xlfn.TEXTAFTER(E7,"("), ")")))) ), _xlfn.TEXTBEFORE(_xlfn.TEXTAFTER(E7,"("), ")"), LEFT(E7, FIND(" ", E7 & " ") - 1) ), "") -> SL-89 | I7: {=_xlfn.LET( _xlpm.txt, E7, _xlpm.afterQty, IFERROR(_xlfn.TEXTAFTER(_xlpm.txt, "QTY:"), ""), _xlpm.numberText, TRIM(_xlfn.TEXTBEFORE(_xlpm.afterQty, " ")), _xlpm.cleanNum, SUBSTITUTE(_xlpm.numberText, ",", ""), IF(ISNUMBER(--_xlpm.cleanNum), --_xlpm.cleanNum, "") )} -> 70056 | J7: {=_xlfn.LET( _xlpm.txt, E7, _xlpm.afterQ, IFERROR(_xlfn.TEXTAFTER(_xlpm.txt,"QTY:"), IFERROR(_xlfn.TEXTAFTER(_xlpm.txt,"QTY "), IFERROR(_xlfn.TEXTAFTER(_xlpm.txt,"(QTY"), ""))), _xlpm.token, TRIM(IF(_xlpm.afterQ="","", _xlfn.TEXTBEFORE(_xlpm.afterQ, "/"))), _xlpm.numPart, IFERROR(LEFT(_xlpm.token, FIND(" ", _xlpm.token)-1), _xlpm.token), _xlpm.cleanNum, SUBSTITUTE(_xlpm.numPart, ",",""), IF(_xlpm.cleanNum="", "", VALUE(_xlpm.cleanNum)) )} -> 70056 | K7: {=_xlfn.LET( _xlpm.txt, E7, _xlpm.afterQ, IFERROR(_xlfn.TEXTAFTER(_xlpm.txt,"QTY:"), IFERROR(_xlfn.TEXTAFTER(_xlpm.txt,"QTY "), IFERROR(_xlfn.TEXTAFTER(_xlpm.txt,"(QTY"), ""))), _xlpm.token, TRIM(IF(_xlpm.afterQ="","", _xlfn.TEXTBEFORE(_xlpm.afterQ, "/"))), _xlpm.unitRaw, UPPER(TRIM(RIGHT(_xlpm.token, LEN(_xlpm.token) - FIND("@", SUBSTITUTE(_xlpm.token," ","@", LEN(_xlpm.token)-LEN(SUBSTITUTE(_xlpm.token," ",""))))))), _xlpm.unitRaw )} -> PCS | L7: =IFERROR(_xlfn.TEXTAFTER(_xlfn.TEXTBEFORE(E7," PER"),"USD ")," ") | M7: =IF(OR(K7="PCS",K7="PC",K7="NOS"),"PCS", IF(OR(K7="SET",K7="SETS"),"SET", IF(K7="PKT","PACK","OTHER"))) -> PCS | N7: 15568 | O7: KGS | P7: 432.15818 | Q7: 6727838.5 | R7: 4.8178169 | S7: 75003.774 | T7: 1890522.7 | U7: =P7+R7 -> 436.97599 | V7: =YEAR(B7) -> 2025 | W7: =IFERROR(VLOOKUP(VALUE(D7),'HSN Lookup'!$A:$B,2,0),"Unknown") -> Household Steel Items | X7: =IF(ISNUMBER(SEARCH("SCRUBBER",G7)),"Scrubber", IF(ISNUMBER(SEARCH("STRAINER",G7)),"Tea Strainer", IF(ISNUMBER(SEARCH("BASKET",G7)),"Basket", IF(ISNUMBER(SEARCH("HANGER",G7)),"Hanger", IF(ISNUMBER(SEARCH("STAND",G7)),"Cloth Stand", IF(ISNUMBER(SEARCH("SPRINKLER",G7)),"Sprinkler", IF(ISNUMBER(SEARCH("HOLDER",G7)),"Holder", IF(ISNUMBER(SEARCH("LUNCH BOX",G7)),"Lunch Box", "Other")))))))) -> Hanger
A8: INNSA1 | B8: 2025-10-06 | C8: 0301049751 | D8: 73239990 | E8: STEEL HANGER 10PCS SET (AM-969) (QTY: 480 SET/USD 0.819 PERSET)STEEL HANGER 10PCS SET (AM-969) (QTY: 480 SET/USD 0.819 PER | F8: {=_xlfn.LET( _xlpm.txt, E8, _xlpm.clean, TRIM(_xlfn.REGEXREPLACE(_xlpm.txt, "\(QTY[^)]*\)", "")), _xlpm.noBrackets, TRIM(SUBSTITUTE(SUBSTITUTE(_xlpm.clean, "(", ""), ")", "")), _xlpm.words, _xlfn.TEXTSPLIT(_xlpm.noBrackets, " "), _xlpm.firstCode, INDEX(_xlpm.words, 1), _xlpm.category, INDEX(_xlpm.words, 2), _xlpm.category )} -> HANGER | G8: {=_xlfn.LET( _xlpm.txt, TRIM(E8), _xlpm.posQTY, IFERROR(FIND("(QTY", _xlpm.txt, 1), 0), _xlpm.firstSpace, FIND(" ", _xlpm.txt & " "), _xlpm.afterFirst, TRIM(MID(_xlpm.txt, _xlpm.firstSpace+1, 9999)), _xlpm.namePart, IF(_xlpm.posQTY>0, _xlfn.TEXTBEFORE(_xlpm.afterFirst, "(QTY"), IFERROR(_xlfn.TEXTBEFORE(_xlpm.afterFirst, "("), _xlpm.afterFirst)), TRIM(_xlpm.namePart) )} -> HANGER 10PCS SET (AM-969) | H8: =IFERROR( IF( AND(ISNUMBER(FIND("(",E8)), NOT(ISNUMBER(SEARCH("QTY", _xlfn.TEXTBEFORE(_xlfn.TEXTAFTER(E8,"("), ")")))) ), _xlfn.TEXTBEFORE(_xlfn.TEXTAFTER(E8,"("), ")"), LEFT(E8, FIND(" ", E8 & " ") - 1) ), "") -> AM-969 | I8: {=_xlfn.LET( _xlpm.txt, E8, _xlpm.afterQty, IFERROR(_xlfn.TEXTAFTER(_xlpm.txt, "QTY:"), ""), _xlpm.numberText, TRIM(_xlfn.TEXTBEFORE(_xlpm.afterQty, " ")), _xlpm.cleanNum, SUBSTITUTE(_xlpm.numberText, ",", ""), IF(ISNUMBER(--_xlpm.cleanNum), --_xlpm.cleanNum, "") )} | J8: {=_xlfn.LET( _xlpm.txt, E8, _xlpm.afterQ, IFERROR(_xlfn.TEXTAFTER(_xlpm.txt,"QTY:"), IFERROR(_xlfn.TEXTAFTER(_xlpm.txt,"QTY "), IFERROR(_xlfn.TEXTAFTER(_xlpm.txt,"(QTY"), ""))), _xlpm.token, TRIM(IF(_xlpm.afterQ="","", _xlfn.TEXTBEFORE(_xlpm.afterQ, "/"))), _xlpm.numPart, IFERROR(LEFT(_xlpm.token, FIND(" ", _xlpm.token)-1), _xlpm.token), _xlpm.cleanNum, SUBSTITUTE(_xlpm.numPart, ",",""), IF(_xlpm.cleanNum="", "", VALUE(_xlpm.cleanNum)) )} -> 480 | K8: {=_xlfn.LET( _xlpm.txt, E8, _xlpm.afterQ, IFERROR(_xlfn.TEXTAFTER(_xlpm.txt,"QTY:"), IFERROR(_xlfn.TEXTAFTER(_xlpm.txt,"QTY "), IFERROR(_xlfn.TEXTAFTER(_xlpm.txt,"(QTY"), ""))), _xlpm.token, TRIM(IF(_xlpm.afterQ="","", _xlfn.TEXTBEFORE(_xlpm.afterQ, "/"))), _xlpm.unitRaw, UPPER(TRIM(RIGHT(_xlpm.token, LEN(_xlpm.token) - FIND("@", SUBSTITUTE(_xlpm.token," ","@", LEN(_xlpm.token)-LEN(SUBSTITUTE(_xlpm.token," ",""))))))), _xlpm.unitRaw )} -> SET | L8: =IFERROR(_xlfn.TEXTAFTER(_xlfn.TEXTBEFORE(E8," PER"),"USD ")," ") -> 0.819 | M8: =IF(OR(K8="PCS",K8="PC",K8="NOS"),"PCS", IF(OR(K8="SET",K8="SETS"),"SET", IF(K8="PKT","PACK","OTHER"))) -> SET | N8: 380 | O8: KGS | P8: 100.44208 | Q8: 38167.99 | R8: 1.1197556 | S8: 425.50713 | T8: 10725.3 | U8: =P8+R8 -> 101.56183 | V8: =YEAR(B8) -> 2025 | W8: =IFERROR(VLOOKUP(VALUE(D8),'HSN Lookup'!$A:$B,2,0),"Unknown") -> Household Steel Items | X8: =IF(ISNUMBER(SEARCH("SCRUBBER",G8)),"Scrubber", IF(ISNUMBER(SEARCH("STRAINER",G8)),"Tea Strainer", IF(ISNUMBER(SEARCH("BASKET",G8)),"Basket", IF(ISNUMBER(SEARCH("HANGER",G8)),"Hanger", IF(ISNUMBER(SEARCH("STAND",G8)),"Cloth Stand", IF(ISNUMBER(SEARCH("SPRINKLER",G8)),"Sprinkler", IF(ISNUMBER(SEARCH("HOLDER",G8)),"Holder", IF(ISNUMBER(SEARCH("LUNCH BOX",G8)),"Lunch Box", "Other")))))))) -> Hanger
A9: INNSA1 | B9: 2025-10-01 | C9: 0301049751 | D9: 73239990 | E9: AM-967 STEEL FRUIT BASKET (QTY 400 PCS/USD 1.031 PER PCS) AM-967 STEEL FRUIT BASKET (QTY 400 PCS/USD 1.031 PER PCS) | F9: {=_xlfn.LET( _xlpm.txt, E9, _xlpm.clean, TRIM(_xlfn.REGEXREPLACE(_xlpm.txt, "\(QTY[^)]*\)", "")), _xlpm.noBrackets, TRIM(SUBSTITUTE(SUBSTITUTE(_xlpm.clean, "(", ""), ")", "")), _xlpm.words, _xlfn.TEXTSPLIT(_xlpm.noBrackets, " "), _xlpm.firstCode, INDEX(_xlpm.words, 1), _xlpm.category, INDEX(_xlpm.words, 2), _xlpm.category )} -> STEEL | G9: {=_xlfn.LET( _xlpm.txt, TRIM(E9), _xlpm.posQTY, IFERROR(FIND("(QTY", _xlpm.txt, 1), 0), _xlpm.firstSpace, FIND(" ", _xlpm.txt & " "), _xlpm.afterFirst, TRIM(MID(_xlpm.txt, _xlpm.firstSpace+1, 9999)), _xlpm.namePart, IF(_xlpm.posQTY>0, _xlfn.TEXTBEFORE(_xlpm.afterFirst, "(QTY"), IFERROR(_xlfn.TEXTBEFORE(_xlpm.afterFirst, "("), _xlpm.afterFirst)), TRIM(_xlpm.namePart) )} -> STEEL FRUIT BASKET | H9: =IFERROR( IF( AND(ISNUMBER(FIND("(",E9)), NOT(ISNUMBER(SEARCH("QTY", _xlfn.TEXTBEFORE(_xlfn.TEXTAFTER(E9,"("), ")")))) ), _xlfn.TEXTBEFORE(_xlfn.TEXTAFTER(E9,"("), ")"), LEFT(E9, FIND(" ", E9 & " ") - 1) ), "") -> AM-967 | I9: {=_xlfn.LET( _xlpm.txt, E9, _xlpm.afterQty, IFERROR(_xlfn.TEXTAFTER(_xlpm.txt, "QTY:"), ""), _xlpm.numberText, TRIM(_xlfn.TEXTBEFORE(_xlpm.afterQty, " ")), _xlpm.cleanNum, SUBSTITUTE(_xlpm.numberText, ",", ""), IF(ISNUMBER(--_xlpm.cleanNum), --_xlpm.cleanNum, "") )} | J9: {=_xlfn.LET( _xlpm.txt, E9, _xlpm.afterQ, IFERROR(_xlfn.TEXTAFTER(_xlpm.txt,"QTY:"), IFERROR(_xlfn.TEXTAFTER(_xlpm.txt,"QTY "), IFERROR(_xlfn.TEXTAFTER(_xlpm.txt,"(QTY"), ""))), _xlpm.token, TRIM(IF(_xlpm.afterQ="","", _xlfn.TEXTBEFORE(_xlpm.afterQ, "/"))), _xlpm.numPart, IFERROR(LEFT(_xlpm.token, FIND(" ", _xlpm.token)-1), _xlpm.token), _xlpm.cleanNum, SUBSTITUTE(_xlpm.numPart, ",",""), IF(_xlpm.cleanNum="", "", VALUE(_xlpm.cleanNum)) )} -> 400 | K9: {=_xlfn.LET( _xlpm.txt, E9, _xlpm.afterQ, IFERROR(_xlfn.TEXTAFTER(_xlpm.txt,"QTY:"), IFERROR(_xlfn.TEXTAFTER(_xlpm.txt,"QTY "), IFERROR(_xlfn.TEXTAFTER(_xlpm.txt,"(QTY"), ""))), _xlpm.token, TRIM(IF(_xlpm.afterQ="","", _xlfn.TEXTBEFORE(_xlpm.afterQ, "/"))), _xlpm.unitRaw, UPPER(TRIM(RIGHT(_xlpm.token, LEN(_xlpm.token) - FIND("@", SUBSTITUTE(_xlpm.token," ","@", LEN(_xlpm.token)-LEN(SUBSTITUTE(_xlpm.token," ",""))))))), _xlpm.unitRaw )} -> PCS | L9: =IFERROR(_xlfn.TEXTAFTER(_xlfn.TEXTBEFORE(E9," PER"),"USD ")," ") -> 1.031 | M9: =IF(OR(K9="PCS",K9="PC",K9="NOS"),"PCS", IF(OR(K9="SET",K9="SETS"),"SET", IF(K9="PKT","PACK","OTHER"))) -> PCS | N9: 460 | O9: KGS | P9: 85.377826 | Q9: 39273.8 | R9: 0.96092095 | S9: 442.02364 | T9: 11036 | U9: =P9+R9 -> 86.338747 | V9: =YEAR(B9) -> 2025 | W9: =IFERROR(VLOOKUP(VALUE(D9),'HSN Lookup'!$A:$B,2,0),"Unknown") -> Household Steel Items | X9: =IF(ISNUMBER(SEARCH("SCRUBBER",G9)),"Scrubber", IF(ISNUMBER(SEARCH("STRAINER",G9)),"Tea Strainer", IF(ISNUMBER(SEARCH("BASKET",G9)),"Basket", IF(ISNUMBER(SEARCH("HANGER",G9)),"Hanger", IF(ISNUMBER(SEARCH("STAND",G9)),"Cloth Stand", IF(ISNUMBER(SEARCH("SPRINKLER",G9)),"Sprinkler", IF(ISNUMBER(SEARCH("HOLDER",G9)),"Holder", IF(ISNUMBER(SEARCH("LUNCH BOX",G9)),"Lunch Box", "Other")))))))) -> Basket
A10: INNSA1 | B10: 2025-10-01 | C10: 0301049751 | D10: 73239990 | E10: AM-966 STEEL FRUIT BASKET (QTY 400 PCS/USD 1.017 PER PCS) AM-966 STEEL FRUIT BASKET (QTY 400 PCS/USD 1.017 PER PCS) | F10: {=_xlfn.LET( _xlpm.txt, E10, _xlpm.clean, TRIM(_xlfn.REGEXREPLACE(_xlpm.txt, "\(QTY[^)]*\)", "")), _xlpm.noBrackets, TRIM(SUBSTITUTE(SUBSTITUTE(_xlpm.clean, "(", ""), ")", "")), _xlpm.words, _xlfn.TEXTSPLIT(_xlpm.noBrackets, " "), _xlpm.firstCode, INDEX(_xlpm.words, 1), _xlpm.category, INDEX(_xlpm.words, 2), _xlpm.category )} -> STEEL | G10: {=_xlfn.LET( _xlpm.txt, TRIM(E10), _xlpm.posQTY, IFERROR(FIND("(QTY", _xlpm.txt, 1), 0), _xlpm.firstSpace, FIND(" ", _xlpm.txt & " "), _xlpm.afterFirst, TRIM(MID(_xlpm.txt, _xlpm.firstSpace+1, 9999)), _xlpm.namePart, IF(_xlpm.posQTY>0, _xlfn.TEXTBEFORE(_xlpm.afterFirst, "(QTY"), IFERROR(_xlfn.TEXTBEFORE(_xlpm.afterFirst, "("), _xlpm.afterFirst)), TRIM(_xlpm.namePart) )} -> STEEL FRUIT BASKET | H10: =IFERROR( IF( AND(ISNUMBER(FIND("(",E10)), NOT(ISNUMBER(SEARCH("QTY", _xlfn.TEXTBEFORE(_xlfn.TEXTAFTER(E10,"("), ")")))) ), _xlfn.TEXTBEFORE(_xlfn.TEXTAFTER(E10,"("), ")"), LEFT(E10, FIND(" ", E10 & " ") - 1) ), "") -> AM-966 | I10: {=_xlfn.LET( _xlpm.txt, E10, _xlpm.afterQty, IFERROR(_xlfn.TEXTAFTER(_xlpm.txt, "QTY:"), ""), _xlpm.numberText, TRIM(_xlfn.TEXTBEFORE(_xlpm.afterQty, " ")), _xlpm.cleanNum, SUBSTITUTE(_xlpm.numberText, ",", ""), IF(ISNUMBER(--_xlpm.cleanNum), --_xlpm.cleanNum, "") )} | J10: {=_xlfn.LET( _xlpm.txt, E10, _xlpm.afterQ, IFERROR(_xlfn.TEXTAFTER(_xlpm.txt,"QTY:"), IFERROR(_xlfn.TEXTAFTER(_xlpm.txt,"QTY "), IFERROR(_xlfn.TEXTAFTER(_xlpm.txt,"(QTY"), ""))), _xlpm.token, TRIM(IF(_xlpm.afterQ="","", _xlfn.TEXTBEFORE(_xlpm.afterQ, "/"))), _xlpm.numPart, IFERROR(LEFT(_xlpm.token, FIND(" ", _xlpm.token)-1), _xlpm.token), _xlpm.cleanNum, SUBSTITUTE(_xlpm.numPart, ",",""), IF(_xlpm.cleanNum="", "", VALUE(_xlpm.cleanNum)) )} -> 400 | K10: {=_xlfn.LET( _xlpm.txt, E10, _xlpm.afterQ, IFERROR(_xlfn.TEXTAFTER(_xlpm.txt,"QTY:"), IFERROR(_xlfn.TEXTAFTER(_xlpm.txt,"QTY "), IFERROR(_xlfn.TEXTAFTER(_xlpm.txt,"(QTY"), ""))), _xlpm.token, TRIM(IF(_xlpm.afterQ="","", _xlfn.TEXTBEFORE(_xlpm.afterQ, "/"))), _xlpm.unitRaw, UPPER(TRIM(RIGHT(_xlpm.token, LEN(_xlpm.token) - FIND("@", SUBSTITUTE(_xlpm.token," ","@", LEN(_xlpm.token)-LEN(SUBSTITUTE(_xlpm.token," ",""))))))), _xlpm.unitRaw )} -> PCS | L10: =IFERROR(_xlfn.TEXTAFTER(_xlfn.TEXTBEFORE(E10," PER"),"USD ")," ") -> 1.017 | M10: =IF(OR(K10="PCS",K10="PC",K10="NOS"),"PCS", IF(OR(K10="SET",K10="SETS"),"SET", IF(K10="PKT","PACK","OTHER"))) -> PCS | N10: 310 | O10: KGS | P10: 124.96932 | Q10: 38740.49 | R10: 1.4065202 | S10: 436.02127 | T10: 10886.1 | U10: =P10+R10 -> 126.37584 | V10: =YEAR(B10) -> 2025 | W10: =IFERROR(VLOOKUP(VALUE(D10),'HSN Lookup'!$A:$B,2,0),"Unknown") -> Household Steel Items | X10: =IF(ISNUMBER(SEARCH("SCRUBBER",G10)),"Scrubber", IF(ISNUMBER(SEARCH("STRAINER",G10)),"Tea Strainer", IF(ISNUMBER(SEARCH("BASKET",G10)),"Basket", IF(ISNUMBER(SEARCH("HANGER",G10)),"Hanger", IF(ISNUMBER(SEARCH("STAND",G10)),"Cloth Stand", IF(ISNUMBER(SEARCH("SPRINKLER",G10)),"Sprinkler", IF(ISNUMBER(SEARCH("HOLDER",G10)),"Holder", IF(ISNUMBER(SEARCH("LUNCH BOX",G10)),"Lunch Box", "Other")))))))) -> Basket
A11: INNSA1 | B11: 2025-10-01 | C11: 0301049751 | D11: 73239990 | E11: AM-965 STEEL SPOON & FORK HOLDER (QTY 480 PCS/USD 0.734 PERPCS)AM-965 STEEL SPOON & FORK HOLDER (QTY 480 PCS/USD 0.734 PER | F11: {=_xlfn.LET( _xlpm.txt, E11, _xlpm.clean, TRIM(_xlfn.REGEXREPLACE(_xlpm.txt, "\(QTY[^)]*\)", "")), _xlpm.noBrackets, TRIM(SUBSTITUTE(SUBSTITUTE(_xlpm.clean, "(", ""), ")", "")), _xlpm.words, _xlfn.TEXTSPLIT(_xlpm.noBrackets, " "), _xlpm.firstCode, INDEX(_xlpm.words, 1), _xlpm.category, INDEX(_xlpm.words, 2), _xlpm.category )} -> STEEL | G11: {=_xlfn.LET( _xlpm.txt, TRIM(E11), _xlpm.posQTY, IFERROR(FIND("(QTY", _xlpm.txt, 1), 0), _xlpm.firstSpace, FIND(" ", _xlpm.txt & " "), _xlpm.afterFirst, TRIM(MID(_xlpm.txt, _xlpm.firstSpace+1, 9999)), _xlpm.namePart, IF(_xlpm.posQTY>0, _xlfn.TEXTBEFORE(_xlpm.afterFirst, "(QTY"), IFERROR(_xlfn.TEXTBEFORE(_xlpm.afterFirst, "("), _xlpm.afterFirst)), TRIM(_xlpm.namePart) )} -> STEEL SPOON & FORK HOLDER | H11: =IFERROR( IF( AND(ISNUMBER(FIND("(",E11)), NOT(ISNUMBER(SEARCH("QTY", _xlfn.TEXTBEFORE(_xlfn.TEXTAFTER(E11,"("), ")")))) ), _xlfn.TEXTBEFORE(_xlfn.TEXTAFTER(E11,"("), ")"), LEFT(E11, FIND(" ", E11 & " ") - 1) ), "") -> AM-965 | I11: {=_xlfn.LET( _xlpm.txt, E11, _xlpm.afterQty, IFERROR(_xlfn.TEXTAFTER(_xlpm.txt, "QTY:"), ""), _xlpm.numberText, TRIM(_xlfn.TEXTBEFORE(_xlpm.afterQty, " ")), _xlpm.cleanNum, SUBSTITUTE(_xlpm.numberText, ",", ""), IF(ISNUMBER(--_xlpm.cleanNum), --_xlpm.cleanNum, "") )} | J11: {=_xlfn.LET( _xlpm.txt, E11, _xlpm.afterQ, IFERROR(_xlfn.TEXTAFTER(_xlpm.txt,"QTY:"), IFERROR(_xlfn.TEXTAFTER(_xlpm.txt,"QTY "), IFERROR(_xlfn.TEXTAFTER(_xlpm.txt,"(QTY"), ""))), _xlpm.token, TRIM(IF(_xlpm.afterQ="","", _xlfn.TEXTBEFORE(_xlpm.afterQ, "/"))), _xlpm.numPart, IFERROR(LEFT(_xlpm.token, FIND(" ", _xlpm.token)-1), _xlpm.token), _xlpm.cleanNum, SUBSTITUTE(_xlpm.numPart, ",",""), IF(_xlpm.cleanNum="", "", VALUE(_xlpm.cleanNum)) )} -> 480 | K11: {=_xlfn.LET( _xlpm.txt, E11, _xlpm.afterQ, IFERROR(_xlfn.TEXTAFTER(_xlpm.txt,"QTY:"), IFERROR(_xlfn.TEXTAFTER(_xlpm.txt,"QTY "), IFERROR(_xlfn.TEXTAFTER(_xlpm.txt,"(QTY"), ""))), _xlpm.token, TRIM(IF(_xlpm.afterQ="","", _xlfn.TEXTBEFORE(_xlpm.afterQ, "/"))), _xlpm.unitRaw, UPPER(TRIM(RIGHT(_xlpm.token, LEN(_xlpm.token) - FIND("@", SUBSTITUTE(_xlpm.token," ","@", LEN(_xlpm.token)-LEN(SUBSTITUTE(_xlpm.token," ",""))))))), _xlpm.unitRaw )} -> PCS | L11: =IFERROR(_xlfn.TEXTAFTER(_xlfn.TEXTBEFORE(E11," PER"),"USD ")," ") -> 0.734 | M11: =IF(OR(K11="PCS",K11="PC",K11="NOS"),"PCS", IF(OR(K11="SET",K11="SETS"),"SET", IF(K11="PKT","PACK","OTHER"))) -> PCS | N11: 168 | O11: KGS | P11: 199.71571 | Q11: 33552.24 | R11: 2.2477852 | S11: 377.62791 | T11: 9428.1 | U11: =P11+R11 -> 201.9635 | V11: =YEAR(B11) -> 2025 | W11: =IFERROR(VLOOKUP(VALUE(D11),'HSN Lookup'!$A:$B,2,0),"Unknown") -> Household Steel Items | X11: =IF(ISNUMBER(SEARCH("SCRUBBER",G11)),"Scrubber", IF(ISNUMBER(SEARCH("STRAINER",G11)),"Tea Strainer", IF(ISNUMBER(SEARCH("BASKET",G11)),"Basket", IF(ISNUMBER(SEARCH("HANGER",G11)),"Hanger", IF(ISNUMBER(SEARCH("STAND",G11)),"Cloth Stand", IF(ISNUMBER(SEARCH("SPRINKLER",G11)),"Sprinkler", IF(ISNUMBER(SEARCH("HOLDER",G11)),"Holder", IF(ISNUMBER(SEARCH("LUNCH BOX",G11)),"Lunch Box", "Other")))))))) -> Holder
A12: INNSA1 | B12: 2025-10-01 | C12: 0301049751 | D12: 73231000 | E12: 8001-2 STEEL SCRUBBER 2 PCS SET (QTY 336000 SETS/USD 0.139 PER SETS)8001-2 STEEL SCRUBBER 2 PCS SET (QTY 336000 SETS/USD 0.139 P | F12: {=_xlfn.LET( _xlpm.txt, E12, _xlpm.clean, TRIM(_xlfn.REGEXREPLACE(_xlpm.txt, "\(QTY[^)]*\)", "")), _xlpm.noBrackets, TRIM(SUBSTITUTE(SUBSTITUTE(_xlpm.clean, "(", ""), ")", "")), _xlpm.words, _xlfn.TEXTSPLIT(_xlpm.noBrackets, " "), _xlpm.firstCode, INDEX(_xlpm.words, 1), _xlpm.category, INDEX(_xlpm.words, 2), _xlpm.category )} -> STEEL | G12: {=_xlfn.LET( _xlpm.txt, TRIM(E12), _xlpm.posQTY, IFERROR(FIND("(QTY", _xlpm.txt, 1), 0), _xlpm.firstSpace, FIND(" ", _xlpm.txt & " "), _xlpm.afterFirst, TRIM(MID(_xlpm.txt, _xlpm.firstSpace+1, 9999)), _xlpm.namePart, IF(_xlpm.posQTY>0, _xlfn.TEXTBEFORE(_xlpm.afterFirst, "(QTY"), IFERROR(_xlfn.TEXTBEFORE(_xlpm.afterFirst, "("), _xlpm.afterFirst)), TRIM(_xlpm.namePart) )} -> STEEL SCRUBBER 2 PCS SET | H12: =IFERROR( IF( AND(ISNUMBER(FIND("(",E12)), NOT(ISNUMBER(SEARCH("QTY", _xlfn.TEXTBEFORE(_xlfn.TEXTAFTER(E12,"("), ")")))) ), _xlfn.TEXTBEFORE(_xlfn.TEXTAFTER(E12,"("), ")"), LEFT(E12, FIND(" ", E12 & " ") - 1) ), "") -> 8001-2 | I12: {=_xlfn.LET( _xlpm.txt, E12, _xlpm.afterQty, IFERROR(_xlfn.TEXTAFTER(_xlpm.txt, "QTY:"), ""), _xlpm.numberText, TRIM(_xlfn.TEXTBEFORE(_xlpm.afterQty, " ")), _xlpm.cleanNum, SUBSTITUTE(_xlpm.numberText, ",", ""), IF(ISNUMBER(--_xlpm.cleanNum), --_xlpm.cleanNum, "") )} | J12: {=_xlfn.LET( _xlpm.txt, E12, _xlpm.afterQ, IFERROR(_xlfn.TEXTAFTER(_xlpm.txt,"QTY:"), IFERROR(_xlfn.TEXTAFTER(_xlpm.txt,"QTY "), IFERROR(_xlfn.TEXTAFTER(_xlpm.txt,"(QTY"), ""))), _xlpm.token, TRIM(IF(_xlpm.afterQ="","", _xlfn.TEXTBEFORE(_xlpm.afterQ, "/"))), _xlpm.numPart, IFERROR(LEFT(_xlpm.token, FIND(" ", _xlpm.token)-1), _xlpm.token), _xlpm.cleanNum, SUBSTITUTE(_xlpm.numPart, ",",""), IF(_xlpm.cleanNum="", "", VALUE(_xlpm.cleanNum)) )} -> 336000 | K12: {=_xlfn.LET( _xlpm.txt, E12, _xlpm.afterQ, IFERROR(_xlfn.TEXTAFTER(_xlpm.txt,"QTY:"), IFERROR(_xlfn.TEXTAFTER(_xlpm.txt,"QTY "), IFERROR(_xlfn.TEXTAFTER(_xlpm.txt,"(QTY"), ""))), _xlpm.token, TRIM(IF(_xlpm.afterQ="","", _xlfn.TEXTBEFORE(_xlpm.afterQ, "/"))), _xlpm.unitRaw, UPPER(TRIM(RIGHT(_xlpm.token, LEN(_xlpm.token) - FIND("@", SUBSTITUTE(_xlpm.token," ","@", LEN(_xlpm.token)-LEN(SUBSTITUTE(_xlpm.token," ",""))))))), _xlpm.unitRaw )} -> SETS | L12: =IFERROR(_xlfn.TEXTAFTER(_xlfn.TEXTBEFORE(E12," PER"),"USD ")," ") -> 0.139 | M12: =IF(OR(K12="PCS",K12="PC",K12="NOS"),"PCS", IF(OR(K12="SET",K12="SETS"),"SET", IF(K12="PKT","PACK","OTHER"))) -> SET | N12: 9800 | O12: KGS | P12: 456.12539 | Q12: 4470028.8 | R12: 5.1336566 | S12: 50309.835 | T12: 1965024.7 | U12: =P12+R12 -> 461.25905 | V12: =YEAR(B12) -> 2025 | W12: =IFERROR(VLOOKUP(VALUE(D12),'HSN Lookup'!$A:$B,2,0),"Unknown") -> Steel Scrubbers | X12: =IF(ISNUMBER(SEARCH("SCRUBBER",G12)),"Scrubber", IF(ISNUMBER(SEARCH("STRAINER",G12)),"Tea Strainer", IF(ISNUMBER(SEARCH("BASKET",G12)),"Basket", IF(ISNUMBER(SEARCH("HANGER",G12)),"Hanger", IF(ISNUMBER(SEARCH("STAND",G12)),"Cloth Stand", IF(ISNUMBER(SEARCH("SPRINKLER",G12)),"Sprinkler", IF(ISNUMBER(SEARCH("HOLDER",G12)),"Holder", IF(ISNUMBER(SEARCH("LUNCH BOX",G12)),"Lunch Box", "Other")))))))) -> Scrubber
A13: INNSA1 | B13: 2025-09-27 | C13: 0301049751 | D13: 73231000 | E13: OKS-4156 STEEL SCRUBBER 6PCS SET (QTY: 93360 PCS /USD 0.228PER PCS)OKS-4156 STEEL SCRUBBER 6PCS SET (QTY: 93360 PCS /USD 0.228 | F13: {=_xlfn.LET( _xlpm.txt, E13, _xlpm.clean, TRIM(_xlfn.REGEXREPLACE(_xlpm.txt, "\(QTY[^)]*\)", "")), _xlpm.noBrackets, TRIM(SUBSTITUTE(SUBSTITUTE(_xlpm.clean, "(", ""), ")", "")), _xlpm.words, _xlfn.TEXTSPLIT(_xlpm.noBrackets, " "), _xlpm.firstCode, INDEX(_xlpm.words, 1), _xlpm.category, INDEX(_xlpm.words, 2), _xlpm.category )} -> STEEL | G13: {=_xlfn.LET( _xlpm.txt, TRIM(E13), _xlpm.posQTY, IFERROR(FIND("(QTY", _xlpm.txt, 1), 0), _xlpm.firstSpace, FIND(" ", _xlpm.txt & " "), _xlpm.afterFirst, TRIM(MID(_xlpm.txt, _xlpm.firstSpace+1, 9999)), _xlpm.namePart, IF(_xlpm.posQTY>0, _xlfn.TEXTBEFORE(_xlpm.afterFirst, "(QTY"), IFERROR(_xlfn.TEXTBEFORE(_xlpm.afterFirst, "("), _xlpm.afterFirst)), TRIM(_xlpm.namePart) )} -> STEEL SCRUBBER 6PCS SET | H13: =IFERROR( IF( AND(ISNUMBER(FIND("(",E13)), NOT(ISNUMBER(SEARCH("QTY", _xlfn.TEXTBEFORE(_xlfn.TEXTAFTER(E13,"("), ")")))) ), _xlfn.TEXTBEFORE(_xlfn.TEXTAFTER(E13,"("), ")"), LEFT(E13, FIND(" ", E13 & " ") - 1) ), "") -> OKS-4156 | I13: {=_xlfn.LET( _xlpm.txt, E13, _xlpm.afterQty, IFERROR(_xlfn.TEXTAFTER(_xlpm.txt, "QTY:"), ""), _xlpm.numberText, TRIM(_xlfn.TEXTBEFORE(_xlpm.afterQty, " ")), _xlpm.cleanNum, SUBSTITUTE(_xlpm.numberText, ",", ""), IF(ISNUMBER(--_xlpm.cleanNum), --_xlpm.cleanNum, "") )} | J13: {=_xlfn.LET( _xlpm.txt, E13, _xlpm.afterQ, IFERROR(_xlfn.TEXTAFTER(_xlpm.txt,"QTY:"), IFERROR(_xlfn.TEXTAFTER(_xlpm.txt,"QTY "), IFERROR(_xlfn.TEXTAFTER(_xlpm.txt,"(QTY"), ""))), _xlpm.token, TRIM(IF(_xlpm.afterQ="","", _xlfn.TEXTBEFORE(_xlpm.afterQ, "/"))), _xlpm.numPart, IFERROR(LEFT(_xlpm.token, FIND(" ", _xlpm.token)-1), _xlpm.token), _xlpm.cleanNum, SUBSTITUTE(_xlpm.numPart, ",",""), IF(_xlpm.cleanNum="", "", VALUE(_xlpm.cleanNum)) )} -> 93360 | K13: {=_xlfn.LET( _xlpm.txt, E13, _xlpm.afterQ, IFERROR(_xlfn.TEXTAFTER(_xlpm.txt,"QTY:"), IFERROR(_xlfn.TEXTAFTER(_xlpm.txt,"QTY "), IFERROR(_xlfn.TEXTAFTER(_xlpm.txt,"(QTY"), ""))), _xlpm.token, TRIM(IF(_xlpm.afterQ="","", _xlfn.TEXTBEFORE(_xlpm.afterQ, "/"))), _xlpm.unitRaw, UPPER(TRIM(RIGHT(_xlpm.token, LEN(_xlpm.token) - FIND("@", SUBSTITUTE(_xlpm.token," ","@", LEN(_xlpm.token)-LEN(SUBSTITUTE(_xlpm.token," ",""))))))), _xlpm.unitRaw )} -> PCS | L13: =IFERROR(_xlfn.TEXTAFTER(_xlfn.TEXTBEFORE(E13," PER"),"USD ")," ") | M13: =IF(OR(K13="PCS",K13="PC",K13="NOS"),"PCS", IF(OR(K13="SET",K13="SETS"),"SET", IF(K13="PKT","PACK","OTHER"))) -> PCS | N13: 7496.03 | O13: KGS | P13: 263.57138 | Q13: 1975739 | R13: 2.9664758 | S13: 22236.792 | T13: 868534.9 | U13: =P13+R13 -> 266.53785 | V13: =YEAR(B13) -> 2025 | W13: =IFERROR(VLOOKUP(VALUE(D13),'HSN Lookup'!$A:$B,2,0),"Unknown") -> Steel Scrubbers | X13: =IF(ISNUMBER(SEARCH("SCRUBBER",G13)),"Scrubber", IF(ISNUMBER(SEARCH("STRAINER",G13)),"Tea Strainer", IF(ISNUMBER(SEARCH("BASKET",G13)),"Basket", IF(ISNUMBER(SEARCH("HANGER",G13)),"Hanger", IF(ISNUMBER(SEARCH("STAND",G13)),"Cloth Stand", IF(ISNUMBER(SEARCH("SPRINKLER",G13)),"Sprinkler", IF(ISNUMBER(SEARCH("HOLDER",G13)),"Holder", IF(ISNUMBER(SEARCH("LUNCH BOX",G13)),"Lunch Box", "Other")))))))) -> Scrubber
A14: INNSA1 | B14: 2025-09-27 | C14: 0301049751 | D14: 73231000 | E14: 8001-2 STEEL SCRUBBER 2PCS SET (QTY: 168000 SETS/USD 0.139 PER SETS)8001-2 STEEL SCRUBBER 2PCS SET (QTY: 168000 SETS/USD 0.139 P | F14: {=_xlfn.LET( _xlpm.txt, E14, _xlpm.clean, TRIM(_xlfn.REGEXREPLACE(_xlpm.txt, "\(QTY[^)]*\)", "")), _xlpm.noBrackets, TRIM(SUBSTITUTE(SUBSTITUTE(_xlpm.clean, "(", ""), ")", "")), _xlpm.words, _xlfn.TEXTSPLIT(_xlpm.noBrackets, " "), _xlpm.firstCode, INDEX(_xlpm.words, 1), _xlpm.category, INDEX(_xlpm.words, 2), _xlpm.category )} -> STEEL | G14: {=_xlfn.LET( _xlpm.txt, TRIM(E14), _xlpm.posQTY, IFERROR(FIND("(QTY", _xlpm.txt, 1), 0), _xlpm.firstSpace, FIND(" ", _xlpm.txt & " "), _xlpm.afterFirst, TRIM(MID(_xlpm.txt, _xlpm.firstSpace+1, 9999)), _xlpm.namePart, IF(_xlpm.posQTY>0, _xlfn.TEXTBEFORE(_xlpm.afterFirst, "(QTY"), IFERROR(_xlfn.TEXTBEFORE(_xlpm.afterFirst, "("), _xlpm.afterFirst)), TRIM(_xlpm.namePart) )} -> STEEL SCRUBBER 2PCS SET | H14: =IFERROR( IF( AND(ISNUMBER(FIND("(",E14)), NOT(ISNUMBER(SEARCH("QTY", _xlfn.TEXTBEFORE(_xlfn.TEXTAFTER(E14,"("), ")")))) ), _xlfn.TEXTBEFORE(_xlfn.TEXTAFTER(E14,"("), ")"), LEFT(E14, FIND(" ", E14 & " ") - 1) ), "") -> 8001-2 | I14: {=_xlfn.LET( _xlpm.txt, E14, _xlpm.afterQty, IFERROR(_xlfn.TEXTAFTER(_xlpm.txt, "QTY:"), ""), _xlpm.numberText, TRIM(_xlfn.TEXTBEFORE(_xlpm.afterQty, " ")), _xlpm.cleanNum, SUBSTITUTE(_xlpm.numberText, ",", ""), IF(ISNUMBER(--_xlpm.cleanNum), --_xlpm.cleanNum, "") )} | J14: {=_xlfn.LET( _xlpm.txt, E14, _xlpm.afterQ, IFERROR(_xlfn.TEXTAFTER(_xlpm.txt,"QTY:"), IFERROR(_xlfn.TEXTAFTER(_xlpm.txt,"QTY "), IFERROR(_xlfn.TEXTAFTER(_xlpm.txt,"(QTY"), ""))), _xlpm.token, TRIM(IF(_xlpm.afterQ="","", _xlfn.TEXTBEFORE(_xlpm.afterQ, "/"))), _xlpm.numPart, IFERROR(LEFT(_xlpm.token, FIND(" ", _xlpm.token)-1), _xlpm.token), _xlpm.cleanNum, SUBSTITUTE(_xlpm.numPart, ",",""), IF(_xlpm.cleanNum="", "", VALUE(_xlpm.cleanNum)) )} -> 168000 | K14: {=_xlfn.LET( _xlpm.txt, E14, _xlpm.afterQ, IFERROR(_xlfn.TEXTAFTER(_xlpm.txt,"QTY:"), IFERROR(_xlfn.TEXTAFTER(_xlpm.txt,"QTY "), IFERROR(_xlfn.TEXTAFTER(_xlpm.txt,"(QTY"), ""))), _xlpm.token, TRIM(IF(_xlpm.afterQ="","", _xlfn.TEXTBEFORE(_xlpm.afterQ, "/"))), _xlpm.unitRaw, UPPER(TRIM(RIGHT(_xlpm.token, LEN(_xlpm.token) - FIND("@", SUBSTITUTE(_xlpm.token," ","@", LEN(_xlpm.token)-LEN(SUBSTITUTE(_xlpm.token," ",""))))))), _xlpm.unitRaw )} -> SETS | L14: =IFERROR(_xlfn.TEXTAFTER(_xlfn.TEXTBEFORE(E14," PER"),"USD ")," ") -> 0.139 | M14: =IF(OR(K14="PCS",K14="PC",K14="NOS"),"PCS", IF(OR(K14="SET",K14="SETS"),"SET", IF(K14="PKT","PACK","OTHER"))) -> SET | N14: 4900 | O14: KGS | P14: 442.07294 | Q14: 2166157.4 | R14: 4.9754973 | S14: 24379.937 | T14: 952242.8 | U14: =P14+R14 -> 447.04843 | V14: =YEAR(B14) -> 2025 | W14: =IFERROR(VLOOKUP(VALUE(D14),'HSN Lookup'!$A:$B,2,0),"Unknown") -> Steel Scrubbers | X14: =IF(ISNUMBER(SEARCH("SCRUBBER",G14)),"Scrubber", IF(ISNUMBER(SEARCH("STRAINER",G14)),"Tea Strainer", IF(ISNUMBER(SEARCH("BASKET",G14)),"Basket", IF(ISNUMBER(SEARCH("HANGER",G14)),"Hanger", IF(ISNUMBER(SEARCH("STAND",G14)),"Cloth Stand", IF(ISNUMBER(SEARCH("SPRINKLER",G14)),"Sprinkler", IF(ISNUMBER(SEARCH("HOLDER",G14)),"Holder", IF(ISNUMBER(SEARCH("LUNCH BOX",G14)),"Lunch Box", "Other")))))))) -> Scrubber
A15: INNSA1 | B15: 2025-09-24 | C15: 0301049751 | D15: 73239990 | E15: AM-321 STEEL DRAINER (QTY:28752 PCS/USD 0.7050 PER PCS) AM-321 STEEL DRAINER (QTY:28752 PCS/USD 0.7050 PER PCS) | F15: {=_xlfn.LET( _xlpm.txt, E15, _xlpm.clean, TRIM(_xlfn.REGEXREPLACE(_xlpm.txt, "\(QTY[^)]*\)", "")), _xlpm.noBrackets, TRIM(SUBSTITUTE(SUBSTITUTE(_xlpm.clean, "(", ""), ")", "")), _xlpm.words, _xlfn.TEXTSPLIT(_xlpm.noBrackets, " "), _xlpm.firstCode, INDEX(_xlpm.words, 1), _xlpm.category, INDEX(_xlpm.words, 2), _xlpm.category )} -> STEEL | G15: {=_xlfn.LET( _xlpm.txt, TRIM(E15), _xlpm.posQTY, IFERROR(FIND("(QTY", _xlpm.txt, 1), 0), _xlpm.firstSpace, FIND(" ", _xlpm.txt & " "), _xlpm.afterFirst, TRIM(MID(_xlpm.txt, _xlpm.firstSpace+1, 9999)), _xlpm.namePart, IF(_xlpm.posQTY>0, _xlfn.TEXTBEFORE(_xlpm.afterFirst, "(QTY"), IFERROR(_xlfn.TEXTBEFORE(_xlpm.afterFirst, "("), _xlpm.afterFirst)), TRIM(_xlpm.namePart) )} -> STEEL DRAINER | H15: =IFERROR( IF( AND(ISNUMBER(FIND("(",E15)), NOT(ISNUMBER(SEARCH("QTY", _xlfn.TEXTBEFORE(_xlfn.TEXTAFTER(E15,"("), ")")))) ), _xlfn.TEXTBEFORE(_xlfn.TEXTAFTER(E15,"("), ")"), LEFT(E15, FIND(" ", E15 & " ") - 1) ), "") -> AM-321 | I15: {=_xlfn.LET( _xlpm.txt, E15, _xlpm.afterQty, IFERROR(_xlfn.TEXTAFTER(_xlpm.txt, "QTY:"), ""), _xlpm.numberText, TRIM(_xlfn.TEXTBEFORE(_xlpm.afterQty, " ")), _xlpm.cleanNum, SUBSTITUTE(_xlpm.numberText, ",", ""), IF(ISNUMBER(--_xlpm.cleanNum), --_xlpm.cleanNum, "") )} -> 28752 | J15: {=_xlfn.LET( _xlpm.txt, E15, _xlpm.afterQ, IFERROR(_xlfn.TEXTAFTER(_xlpm.txt,"QTY:"), IFERROR(_xlfn.TEXTAFTER(_xlpm.txt,"QTY "), IFERROR(_xlfn.TEXTAFTER(_xlpm.txt,"(QTY"), ""))), _xlpm.token, TRIM(IF(_xlpm.afterQ="","", _xlfn.TEXTBEFORE(_xlpm.afterQ, "/"))), _xlpm.numPart, IFERROR(LEFT(_xlpm.token, FIND(" ", _xlpm.token)-1), _xlpm.token), _xlpm.cleanNum, SUBSTITUTE(_xlpm.numPart, ",",""), IF(_xlpm.cleanNum="", "", VALUE(_xlpm.cleanNum)) )} -> 28752 | K15: {=_xlfn.LET( _xlpm.txt, E15, _xlpm.afterQ, IFERROR(_xlfn.TEXTAFTER(_xlpm.txt,"QTY:"), IFERROR(_xlfn.TEXTAFTER(_xlpm.txt,"QTY "), IFERROR(_xlfn.TEXTAFTER(_xlpm.txt,"(QTY"), ""))), _xlpm.token, TRIM(IF(_xlpm.afterQ="","", _xlfn.TEXTBEFORE(_xlpm.afterQ, "/"))), _xlpm.unitRaw, UPPER(TRIM(RIGHT(_xlpm.token, LEN(_xlpm.token) - FIND("@", SUBSTITUTE(_xlpm.token," ","@", LEN(_xlpm.token)-LEN(SUBSTITUTE(_xlpm.token," ",""))))))), _xlpm.unitRaw )} -> PCS | L15: =IFERROR(_xlfn.TEXTAFTER(_xlfn.TEXTBEFORE(E15," PER"),"USD ")," ") -> 0.7050 | M15: =IF(OR(K15="PCS",K15="PC",K15="NOS"),"PCS", IF(OR(K15="SET",K15="SETS"),"SET", IF(K15="PKT","PACK","OTHER"))) -> PCS | N15: 3953.4 | O15: KGS | P15: 492.73197 | Q15: 1947966.6 | R15: 5.5456609 | S15: 21924.216 | T15: 547378.6 | U15: =P15+R15 -> 498.27763 | V15: =YEAR(B15) -> 2025 | W15: =IFERROR(VLOOKUP(VALUE(D15),'HSN Lookup'!$A:$B,2,0),"Unknown") -> Household Steel Items | X15: =IF(ISNUMBER(SEARCH("SCRUBBER",G15)),"Scrubber", IF(ISNUMBER(SEARCH("STRAINER",G15)),"Tea Strainer", IF(ISNUMBER(SEARCH("BASKET",G15)),"Basket", IF(ISNUMBER(SEARCH("HANGER",G15)),"Hanger", IF(ISNUMBER(SEARCH("STAND",G15)),"Cloth Stand", IF(ISNUMBER(SEARCH("SPRINKLER",G15)),"Sprinkler", IF(ISNUMBER(SEARCH("HOLDER",G15)),"Holder", IF(ISNUMBER(SEARCH("LUNCH BOX",G15)),"Lunch Box", "Other")))))))) -> Other
... A656: INNSA1 | B656: 2023-06-17 | C656: 0301049751 | D656: 73239990 | E656: STAINLESS STEEL COLA BOTTLE 750ML SK750 (SL-01) (QTY: 3960 PCS / USD 1.195 PER PCS) | F656: {=_xlfn.LET( _xlpm.txt, E656, _xlpm.clean, TRIM(_xlfn.REGEXREPLACE(_xlpm.txt, "\(QTY[^)]*\)", "")), _xlpm.noBrackets, TRIM(SUBSTITUTE(SUBSTITUTE(_xlpm.clean, "(", ""), ")", "")), _xlpm.words, _xlfn.TEXTSPLIT(_xlpm.noBrackets, " "), _xlpm.firstCode, INDEX(_xlpm.words, 1), _xlpm.category, INDEX(_xlpm.words, 2), _xlpm.category )} -> STEEL | G656: {=_xlfn.LET( _xlpm.txt, TRIM(E656), _xlpm.posQTY, IFERROR(FIND("(QTY", _xlpm.txt, 1), 0), _xlpm.firstSpace, FIND(" ", _xlpm.txt & " "), _xlpm.afterFirst, TRIM(MID(_xlpm.txt, _xlpm.firstSpace+1, 9999)), _xlpm.namePart, IF(_xlpm.posQTY>0, _xlfn.TEXTBEFORE(_xlpm.afterFirst, "(QTY"), IFERROR(_xlfn.TEXTBEFORE(_xlpm.afterFirst, "("), _xlpm.afterFirst)), TRIM(_xlpm.namePart) )} -> STEEL COLA BOTTLE 750ML SK750 (SL-01) | H656: =IFERROR( IF( AND(ISNUMBER(FIND("(",E656)), NOT(ISNUMBER(SEARCH("QTY", _xlfn.TEXTBEFORE(_xlfn.TEXTAFTER(E656,"("), ")")))) ), _xlfn.TEXTBEFORE(_xlfn.TEXTAFTER(E656,"("), ")"), LEFT(E656, FIND(" ", E656 & " ") - 1) ), "") -> SL-01 | I656: {=_xlfn.LET( _xlpm.txt, E656, _xlpm.afterQty, IFERROR(_xlfn.TEXTAFTER(_xlpm.txt, "QTY:"), ""), _xlpm.numberText, TRIM(_xlfn.TEXTBEFORE(_xlpm.afterQty, " ")), _xlpm.cleanNum, SUBSTITUTE(_xlpm.numberText, ",", ""), IF(ISNUMBER(--_xlpm.cleanNum), --_xlpm.cleanNum, "") )} | J656: {=_xlfn.LET( _xlpm.txt, E656, _xlpm.afterQ, IFERROR(_xlfn.TEXTAFTER(_xlpm.txt,"QTY:"), IFERROR(_xlfn.TEXTAFTER(_xlpm.txt,"QTY "), IFERROR(_xlfn.TEXTAFTER(_xlpm.txt,"(QTY"), ""))), _xlpm.token, TRIM(IF(_xlpm.afterQ="","", _xlfn.TEXTBEFORE(_xlpm.afterQ, "/"))), _xlpm.numPart, IFERROR(LEFT(_xlpm.token, FIND(" ", _xlpm.token)-1), _xlpm.token), _xlpm.cleanNum, SUBSTITUTE(_xlpm.numPart, ",",""), IF(_xlpm.cleanNum="", "", VALUE(_xlpm.cleanNum)) )} -> 3960 | K656: {=_xlfn.LET( _xlpm.txt, E656, _xlpm.afterQ, IFERROR(_xlfn.TEXTAFTER(_xlpm.txt,"QTY:"), IFERROR(_xlfn.TEXTAFTER(_xlpm.txt,"QTY "), IFERROR(_xlfn.TEXTAFTER(_xlpm.txt,"(QTY"), ""))), _xlpm.token, TRIM(IF(_xlpm.afterQ="","", _xlfn.TEXTBEFORE(_xlpm.afterQ, "/"))), _xlpm.unitRaw, UPPER(TRIM(RIGHT(_xlpm.token, LEN(_xlpm.token) - FIND("@", SUBSTITUTE(_xlpm.token," ","@", LEN(_xlpm.token)-LEN(SUBSTITUTE(_xlpm.token," ",""))))))), _xlpm.unitRaw )} -> PCS | L656: =IFERROR(_xlfn.TEXTAFTER(_xlfn.TEXTBEFORE(E656," PER"),"USD ")," ") -> 1.195 | M656: =IF(OR(K656="PCS",K656="PC",K656="NOS"),"PCS", IF(OR(K656="SET",K656="SETS"),"SET", IF(K656="PKT","PACK","OTHER"))) -> PCS | N656: 759 | O656: KGS | P656: 539.56523 | Q656: 409530.01 | R656: 6.4968721 | S656: 4931.1259 | T656: 150051.8 | U656: =P656+R656 -> 546.0621 | V656: =YEAR(B656) -> 2023 | W656: =IFERROR(VLOOKUP(VALUE(D656),'HSN Lookup'!$A:$B,2,0),"Unknown") -> Household Steel Items | X656: =IF(ISNUMBER(SEARCH("SCRUBBER",G656)),"Scrubber", IF(ISNUMBER(SEARCH("STRAINER",G656)),"Tea Strainer", IF(ISNUMBER(SEARCH("BASKET",G656)),"Basket", IF(ISNUMBER(SEARCH("HANGER",G656)),"Hanger", IF(ISNUMBER(SEARCH("STAND",G656)),"Cloth Stand", IF(ISNUMBER(SEARCH("SPRINKLER",G656)),"Sprinkler", IF(ISNUMBER(SEARCH("HOLDER",G656)),"Holder", IF(ISNUMBER(SEARCH("LUNCH BOX",G656)),"Lunch Box", "Other")))))))) -> Other
A657: INNSA1 | B657: 2023-06-14 | C657: 0301049751 | D657: 73239990 | E657: STAINLESS STEELSPORTS BOTTLE 650ML S115 (NP-21) (QTY: 20340PCS / USD 1.040 PER PCS) | G657: {=_xlfn.LET( _xlpm.txt, TRIM(E657), _xlpm.posQTY, IFERROR(FIND("(QTY", _xlpm.txt, 1), 0), _xlpm.firstSpace, FIND(" ", _xlpm.txt & " "), _xlpm.afterFirst, TRIM(MID(_xlpm.txt, _xlpm.firstSpace+1, 9999)), _xlpm.namePart, IF(_xlpm.posQTY>0, _xlfn.TEXTBEFORE(_xlpm.afterFirst, "(QTY"), IFERROR(_xlfn.TEXTBEFORE(_xlpm.afterFirst, "("), _xlpm.afterFirst)), TRIM(_xlpm.namePart) )} -> STEELSPORTS BOTTLE 650ML S115 (NP-21) | H657: =IFERROR( IF( AND(ISNUMBER(FIND("(",E657)), NOT(ISNUMBER(SEARCH("QTY", _xlfn.TEXTBEFORE(_xlfn.TEXTAFTER(E657,"("), ")")))) ), _xlfn.TEXTBEFORE(_xlfn.TEXTAFTER(E657,"("), ")"), LEFT(E657, FIND(" ", E657 & " ") - 1) ), "") -> NP-21 | I657: {=_xlfn.LET( _xlpm.txt, E657, _xlpm.afterQty, IFERROR(_xlfn.TEXTAFTER(_xlpm.txt, "QTY:"), ""), _xlpm.numberText, TRIM(_xlfn.TEXTBEFORE(_xlpm.afterQty, " ")), _xlpm.cleanNum, SUBSTITUTE(_xlpm.numberText, ",", ""), IF(ISNUMBER(--_xlpm.cleanNum), --_xlpm.cleanNum, "") )} | J657: {=_xlfn.LET( _xlpm.txt, E657, _xlpm.afterQ, IFERROR(_xlfn.TEXTAFTER(_xlpm.txt,"QTY:"), IFERROR(_xlfn.TEXTAFTER(_xlpm.txt,"QTY "), IFERROR(_xlfn.TEXTAFTER(_xlpm.txt,"(QTY"), ""))), _xlpm.token, TRIM(IF(_xlpm.afterQ="","", _xlfn.TEXTBEFORE(_xlpm.afterQ, "/"))), _xlpm.numPart, IFERROR(LEFT(_xlpm.token, FIND(" ", _xlpm.token)-1), _xlpm.token), _xlpm.cleanNum, SUBSTITUTE(_xlpm.numPart, ",",""), IF(_xlpm.cleanNum="", "", VALUE(_xlpm.cleanNum)) )} -> #VALUE! | K657: {=_xlfn.LET( _xlpm.txt, E657, _xlpm.afterQ, IFERROR(_xlfn.TEXTAFTER(_xlpm.txt,"QTY:"), IFERROR(_xlfn.TEXTAFTER(_xlpm.txt,"QTY "), IFERROR(_xlfn.TEXTAFTER(_xlpm.txt,"(QTY"), ""))), _xlpm.token, TRIM(IF(_xlpm.afterQ="","", _xlfn.TEXTBEFORE(_xlpm.afterQ, "/"))), _xlpm.unitRaw, UPPER(TRIM(RIGHT(_xlpm.token, LEN(_xlpm.token) - FIND("@", SUBSTITUTE(_xlpm.token," ","@", LEN(_xlpm.token)-LEN(SUBSTITUTE(_xlpm.token," ",""))))))), _xlpm.unitRaw )} -> #VALUE! | L657: =IFERROR(_xlfn.TEXTAFTER(_xlfn.TEXTBEFORE(E657," PER"),"USD ")," ") -> 1.040 | M657: =IF(OR(K657="PCS",K657="PC",K657="NOS"),"PCS", IF(OR(K657="SET",K657="SETS"),"SET", IF(K657="PKT","PACK","OTHER"))) -> #VALUE! | N657: 3616 | O657: KGS | P657: 509.02757 | Q657: 1840643.7 | R657: 6.103448 | S657: 22070.068 | T657: 674411.8 | U657: =P657+R657 -> 515.13101 | V657: =YEAR(B657) -> 2023 | W657: =IFERROR(VLOOKUP(VALUE(D657),'HSN Lookup'!$A:$B,2,0),"Unknown") -> Household Steel Items | X657: =IF(ISNUMBER(SEARCH("SCRUBBER",G657)),"Scrubber", IF(ISNUMBER(SEARCH("STRAINER",G657)),"Tea Strainer", IF(ISNUMBER(SEARCH("BASKET",G657)),"Basket", IF(ISNUMBER(SEARCH("HANGER",G657)),"Hanger", IF(ISNUMBER(SEARCH("STAND",G657)),"Cloth Stand", IF(ISNUMBER(SEARCH("SPRINKLER",G657)),"Sprinkler", IF(ISNUMBER(SEARCH("HOLDER",G657)),"Holder", IF(ISNUMBER(SEARCH("LUNCH BOX",G657)),"Lunch Box", "Other")))))))) -> Other
A658: INNSA1 | B658: 2023-06-14 | C658: 0301049751 | D658: 73239990 | E658: STAINLESS STEEL COLA BOTTLE 750ML SK750 (SL-01) (QTY: 21216PCS / USD 1.195 PER PCS) | G658: {=_xlfn.LET( _xlpm.txt, TRIM(E658), _xlpm.posQTY, IFERROR(FIND("(QTY", _xlpm.txt, 1), 0), _xlpm.firstSpace, FIND(" ", _xlpm.txt & " "), _xlpm.afterFirst, TRIM(MID(_xlpm.txt, _xlpm.firstSpace+1, 9999)), _xlpm.namePart, IF(_xlpm.posQTY>0, _xlfn.TEXTBEFORE(_xlpm.afterFirst, "(QTY"), IFERROR(_xlfn.TEXTBEFORE(_xlpm.afterFirst, "("), _xlpm.afterFirst)), TRIM(_xlpm.namePart) )} -> STEEL COLA BOTTLE 750ML SK750 (SL-01) | H658: =IFERROR( IF( AND(ISNUMBER(FIND("(",E658)), NOT(ISNUMBER(SEARCH("QTY", _xlfn.TEXTBEFORE(_xlfn.TEXTAFTER(E658,"("), ")")))) ), _xlfn.TEXTBEFORE(_xlfn.TEXTAFTER(E658,"("), ")"), LEFT(E658, FIND(" ", E658 & " ") - 1) ), "") -> SL-01 | I658: {=_xlfn.LET( _xlpm.txt, E658, _xlpm.afterQty, IFERROR(_xlfn.TEXTAFTER(_xlpm.txt, "QTY:"), ""), _xlpm.numberText, TRIM(_xlfn.TEXTBEFORE(_xlpm.afterQty, " ")), _xlpm.cleanNum, SUBSTITUTE(_xlpm.numberText, ",", ""), IF(ISNUMBER(--_xlpm.cleanNum), --_xlpm.cleanNum, "") )} | J658: {=_xlfn.LET( _xlpm.txt, E658, _xlpm.afterQ, IFERROR(_xlfn.TEXTAFTER(_xlpm.txt,"QTY:"), IFERROR(_xlfn.TEXTAFTER(_xlpm.txt,"QTY "), IFERROR(_xlfn.TEXTAFTER(_xlpm.txt,"(QTY"), ""))), _xlpm.token, TRIM(IF(_xlpm.afterQ="","", _xlfn.TEXTBEFORE(_xlpm.afterQ, "/"))), _xlpm.numPart, IFERROR(LEFT(_xlpm.token, FIND(" ", _xlpm.token)-1), _xlpm.token), _xlpm.cleanNum, SUBSTITUTE(_xlpm.numPart, ",",""), IF(_xlpm.cleanNum="", "", VALUE(_xlpm.cleanNum)) )} -> #VALUE! | K658: {=_xlfn.LET( _xlpm.txt, E658, _xlpm.afterQ, IFERROR(_xlfn.TEXTAFTER(_xlpm.txt,"QTY:"), IFERROR(_xlfn.TEXTAFTER(_xlpm.txt,"QTY "), IFERROR(_xlfn.TEXTAFTER(_xlpm.txt,"(QTY"), ""))), _xlpm.token, TRIM(IF(_xlpm.afterQ="","", _xlfn.TEXTBEFORE(_xlpm.afterQ, "/"))), _xlpm.unitRaw, UPPER(TRIM(RIGHT(_xlpm.token, LEN(_xlpm.token) - FIND("@", SUBSTITUTE(_xlpm.token," ","@", LEN(_xlpm.token)-LEN(SUBSTITUTE(_xlpm.token," ",""))))))), _xlpm.unitRaw )} -> #VALUE! | L658: =IFERROR(_xlfn.TEXTAFTER(_xlfn.TEXTBEFORE(E658," PER"),"USD ")," ") -> 1.195 | M658: =IF(OR(K658="PCS",K658="PC",K658="NOS"),"PCS", IF(OR(K658="SET",K658="SETS"),"SET", IF(K658="PKT","PACK","OTHER"))) -> #VALUE! | N658: 4066 | O658: KGS | P658: 542.50879 | Q658: 2206057.7 | R658: 6.5049015 | S658: 26451.532 | T658: 808299.6 | U658: =P658+R658 -> 549.01369 | V658: =YEAR(B658) -> 2023 | W658: =IFERROR(VLOOKUP(VALUE(D658),'HSN Lookup'!$A:$B,2,0),"Unknown") -> Household Steel Items | X658: =IF(ISNUMBER(SEARCH("SCRUBBER",G658)),"Scrubber", IF(ISNUMBER(SEARCH("STRAINER",G658)),"Tea Strainer", IF(ISNUMBER(SEARCH("BASKET",G658)),"Basket", IF(ISNUMBER(SEARCH("HANGER",G658)),"Hanger", IF(ISNUMBER(SEARCH("STAND",G658)),"Cloth Stand", IF(ISNUMBER(SEARCH("SPRINKLER",G658)),"Sprinkler", IF(ISNUMBER(SEARCH("HOLDER",G658)),"Holder", IF(ISNUMBER(SEARCH("LUNCH BOX",G658)),"Lunch Box", "Other")))))))) -> Other
A659: INNSA1 | B659: 2023-06-13 | C659: 0301049751 | D659: 73231000 | E659: STEEL SCRUBBER 2PCS SET (ITEM NO: 8001-2) (QTY: 168120 SETS& 0.16 USD PER SET) | G659: {=_xlfn.LET( _xlpm.txt, TRIM(E659), _xlpm.posQTY, IFERROR(FIND("(QTY", _xlpm.txt, 1), 0), _xlpm.firstSpace, FIND(" ", _xlpm.txt & " "), _xlpm.afterFirst, TRIM(MID(_xlpm.txt, _xlpm.firstSpace+1, 9999)), _xlpm.namePart, IF(_xlpm.posQTY>0, _xlfn.TEXTBEFORE(_xlpm.afterFirst, "(QTY"), IFERROR(_xlfn.TEXTBEFORE(_xlpm.afterFirst, "("), _xlpm.afterFirst)), TRIM(_xlpm.namePart) )} -> SCRUBBER 2PCS SET (ITEM NO: 8001-2) | H659: =IFERROR( IF( AND(ISNUMBER(FIND("(",E659)), NOT(ISNUMBER(SEARCH("QTY", _xlfn.TEXTBEFORE(_xlfn.TEXTAFTER(E659,"("), ")")))) ), _xlfn.TEXTBEFORE(_xlfn.TEXTAFTER(E659,"("), ")"), LEFT(E659, FIND(" ", E659 & " ") - 1) ), "") -> ITEM NO: 8001-2 | I659: {=_xlfn.LET( _xlpm.txt, E659, _xlpm.afterQty, IFERROR(_xlfn.TEXTAFTER(_xlpm.txt, "QTY:"), ""), _xlpm.numberText, TRIM(_xlfn.TEXTBEFORE(_xlpm.afterQty, " ")), _xlpm.cleanNum, SUBSTITUTE(_xlpm.numberText, ",", ""), IF(ISNUMBER(--_xlpm.cleanNum), --_xlpm.cleanNum, "") )} | J659: {=_xlfn.LET( _xlpm.txt, E659, _xlpm.afterQ, IFERROR(_xlfn.TEXTAFTER(_xlpm.txt,"QTY:"), IFERROR(_xlfn.TEXTAFTER(_xlpm.txt,"QTY "), IFERROR(_xlfn.TEXTAFTER(_xlpm.txt,"(QTY"), ""))), _xlpm.token, TRIM(IF(_xlpm.afterQ="","", _xlfn.TEXTBEFORE(_xlpm.afterQ, "/"))), _xlpm.numPart, IFERROR(LEFT(_xlpm.token, FIND(" ", _xlpm.token)-1), _xlpm.token), _xlpm.cleanNum, SUBSTITUTE(_xlpm.numPart, ",",""), IF(_xlpm.cleanNum="", "", VALUE(_xlpm.cleanNum)) )} -> #N/A | K659: {=_xlfn.LET( _xlpm.txt, E659, _xlpm.afterQ, IFERROR(_xlfn.TEXTAFTER(_xlpm.txt,"QTY:"), IFERROR(_xlfn.TEXTAFTER(_xlpm.txt,"QTY "), IFERROR(_xlfn.TEXTAFTER(_xlpm.txt,"(QTY"), ""))), _xlpm.token, TRIM(IF(_xlpm.afterQ="","", _xlfn.TEXTBEFORE(_xlpm.afterQ, "/"))), _xlpm.unitRaw, UPPER(TRIM(RIGHT(_xlpm.token, LEN(_xlpm.token) - FIND("@", SUBSTITUTE(_xlpm.token," ","@", LEN(_xlpm.token)-LEN(SUBSTITUTE(_xlpm.token," ",""))))))), _xlpm.unitRaw )} -> #N/A | L659: =IFERROR(_xlfn.TEXTAFTER(_xlfn.TEXTBEFORE(E659," PER"),"USD ")," ") | M659: =IF(OR(K659="PCS",K659="PC",K659="NOS"),"PCS", IF(OR(K659="SET",K659="SETS"),"SET", IF(K659="PKT","PACK","OTHER"))) -> #N/A | N659: 4903 | O659: KGS | P659: 466.91972 | Q659: 2289307.4 | R659: 5.5985578 | S659: 27449.729 | T659: 1006379.5 | U659: =P659+R659 -> 472.51828 | V659: =YEAR(B659) -> 2023 | W659: =IFERROR(VLOOKUP(VALUE(D659),'HSN Lookup'!$A:$B,2,0),"Unknown") -> Steel Scrubbers | X659: =IF(ISNUMBER(SEARCH("SCRUBBER",G659)),"Scrubber", IF(ISNUMBER(SEARCH("STRAINER",G659)),"Tea Strainer", IF(ISNUMBER(SEARCH("BASKET",G659)),"Basket", IF(ISNUMBER(SEARCH("HANGER",G659)),"Hanger", IF(ISNUMBER(SEARCH("STAND",G659)),"Cloth Stand", IF(ISNUMBER(SEARCH("SPRINKLER",G659)),"Sprinkler", IF(ISNUMBER(SEARCH("HOLDER",G659)),"Holder", IF(ISNUMBER(SEARCH("LUNCH BOX",G659)),"Lunch Box", "Other")))))))) -> Scrubber
